Workbook
Name Taper_rate: 'DCF Model'!$C$21
Name Tax_rate: 'DCF Model'!$C$27:$C$27

Sheet DCF Model
B2: Discounted Cashflow Model
B3: Financial Modelling Course
B6: Company Overview
B7: Trent LTD is the Retal arm of the TATA Group, Operatng multiple retail formats
B9: WestSide- Depatrment Store chain 248 Stores
B10: Zudio- Value Fashion Retail Chain 766 stores
B11: Star Market- Hyper Market Format 78 Stores
B13: Total Store Count : 1000+ stores across 240+ Cities I Retail Area: ~13.6 Million Sqft
B16: Key Assumption And Methodology
B17: Parameter | C17: Value | D17: Rationale
B18: Valuation Date
B19: Projection Period
C20: 0.2 | D20: Based On management guidance
B21: Annual Growth Tapering | C21: 0.02
B23: Terminal Growth Rate | C23: 0.06 | D23: Conservative long term growth considering India's GDP and retail sector potential
B25: Risk Free Rate (RF) | C25: 0.065 | D25: India 10 year bond yield
B26: EquityRisk Premium (ERP) | C26: =12%-C25 -> 0.055 | D26: Exprcted return over RFR for equity investors
B27: Tax Rate | C27: 0.25 | D27: Effective Tax Rate based of historical performance
B30: Income Statement
B31: Particulars | C31: 44286 | D31: 44651 | E31: 45016 | F31: 45382 | G31: 45747 | H31: CAGR
B32: Sales | C32: ='Data Sheet'!F17 -> 2592.96 | D32: ='Data Sheet'!G17 -> 4498.02 | E32: ='Data Sheet'!H17 -> 8242.02 | F32: ='Data Sheet'!I17 -> 12375.11 | G32: ='Data Sheet'!J17 -> 17134.61
B33: % Of growth | D33: =D32/C32-1 -> 0.73470474 | E33: =E32/D32-1 -> 0.83236624 | F33: =F32/E32-1 -> 0.50146566 | G33: =G32/F32-1 -> 0.38460264 | H33: =_xlfn.RRI(4,C32,G32) -> 0.60331775
B34: COGS | C34: =SUM('Data Sheet'!F18,-'Data Sheet'!F19,'Data Sheet'!F20:F21) -> 1675.41 | D34: =SUM('Data Sheet'!G18,-'Data Sheet'!G19,'Data Sheet'!G20:G21) -> 2680.57 | E34: =SUM('Data Sheet'!H18,-'Data Sheet'!H19,'Data Sheet'!H20:H21) -> 5076.01 | F34: =SUM('Data Sheet'!I18,-'Data Sheet'!I19,'Data Sheet'!I20:I21) -> 7452.64 | G34: =SUM('Data Sheet'!J18,-'Data Sheet'!J19,'Data Sheet'!J20:J21) -> 10408.8
B35: % of Revenue | C35: =C34/C32 -> 0.646138 | D35: =D34/D32 -> 0.59594444 | E35: =E34/E32 -> 0.61586965 | F35: =F34/F32 -> 0.60222818 | G35: =G34/G32 -> 0.60747224
B36: Gross Profit | C36: =C32-C34 -> 917.55 | D36: =D32-D34 -> 1817.45 | E36: =E32-E34 -> 3166.01 | F36: =F32-F34 -> 4922.47 | G36: =G32-G34 -> 6725.81
B37: % Margin | C37: =C36/C32 -> 0.353862 | D37: =D36/D32 -> 0.40405556 | E37: =E36/E32 -> 0.38413035 | F37: =F36/F32 -> 0.39777182 | G37: =G36/G32 -> 0.39252776
B38: Operating Expenses | C38: =SUM('Data Sheet'!F22:F24) -> 803.68 | D38: =SUM('Data Sheet'!G22:G24) -> 1222.73 | E38: =SUM('Data Sheet'!H22:H24) -> 2051.86 | F38: =SUM('Data Sheet'!I22:I24) -> 2951.78 | G38: =SUM('Data Sheet'!J22:J24) -> 3905.85
B39: % Revenue | C39: =C38/C32 -> 0.30994693 | D39: =D38/D32 -> 0.27183739 | E39: =E38/E32 -> 0.24895111 | F39: =F38/F32 -> 0.23852556 | G39: =G38/G32 -> 0.22795091
B40: EBITDA | C40: =C36-C38 -> 113.87 | D40: =D36-D38 -> 594.72 | E40: =E36-E38 -> 1114.15 | F40: =F36-F38 -> 1970.69 | G40: =G36-G38 -> 2819.96
B41: % Margin | C41: =C40/C32 -> 0.043915062 | D41: =D40/D32 -> 0.13221818 | E41: =E40/E32 -> 0.13517924 | F41: =F40/F32 -> 0.15924626 | G41: =G40/G32 -> 0.16457684
B42: Depreciation | C42: ='Data Sheet'!F26 -> 257.3 | D42: ='Data Sheet'!G26 -> 310.82 | E42: ='Data Sheet'!H26 -> 493.69 | F42: ='Data Sheet'!I26 -> 671.11 | G42: ='Data Sheet'!J26 -> 895.18
B43: % Of Sales | C43: =C42/C32 -> 0.099230223 | D43: =D42/D32 -> 0.069101516 | E43: =E42/E32 -> 0.059899151 | F43: =F42/F32 -> 0.054230629 | G43: =G42/G32 -> 0.052243967
B44: EBIT | C44: =C40-C42 -> -143.43 | D44: =D40-D42 -> 283.9 | E44: =E40-E42 -> 620.46 | F44: =F40-F42 -> 1299.58 | G44: =G40-G42 -> 1924.78
B45: % Margin | C45: =C44/C32 -> -0.055315161 | D45: =D44/D32 -> 0.06311666 | E45: =E44/E32 -> 0.075280089 | F45: =F44/F32 -> 0.10501563 | G45: =G44/G32 -> 0.11233287
B46: Other Income | C46: ='Data Sheet'!F25 -> 199.4 | D46: ='Data Sheet'!G25 -> 152.16 | E46: ='Data Sheet'!H25 -> 340.6 | F46: ='Data Sheet'!I25 -> 988.91 | G46: ='Data Sheet'!J25 -> 305.06
B47: Interest | C47: ='Data Sheet'!F27 -> 260.79 | D47: ='Data Sheet'!G27 -> 324.84 | E47: ='Data Sheet'!H27 -> 408.99 | F47: ='Data Sheet'!I27 -> 367.66 | G47: ='Data Sheet'!J27 -> 200.1
B48: % debt | C48: =C47/'Data Sheet'!F59 -> 0.087996815 | D48: =D47/'Data Sheet'!G59 -> 0.068743969 | E48: =E47/'Data Sheet'!H59 -> 0.09161675 | F48: =F47/'Data Sheet'!I59 -> 0.20973308 | G48: =G47/'Data Sheet'!J59 -> 0.08944256
B49: Profit Before Tax | C49: =C44+C46-C47 -> -204.82 | D49: =D44+D46-D47 -> 111.22 | E49: =E44+E46-E47 -> 552.07 | F49: =F44+F46-F47 -> 1920.83 | G49: =G44+G46-G47 -> 2029.74
B50: % of Revenue | C50: =C49/C32 -> -0.078990806 | D50: =D49/D32 -> 0.024726435 | E50: =E49/E32 -> 0.066982366 | F50: =F49/F32 -> 0.15521721 | G50: =G49/G32 -> 0.11845849
B51: Tax | C51: ='Data Sheet'!F29 -> -23.69 | D51: ='Data Sheet'!G29 -> 76.62 | E51: ='Data Sheet'!H29 -> 158.44 | F51: ='Data Sheet'!I29 -> 443.37 | G51: ='Data Sheet'!J29 -> 495.33
...

Sheet Comps
C4: Comps Data
C6: Name | D6: CMP Rs. | E6: Mar Cap Rs.Cr. | F6: Debt Rs.Cr. | G6: Debt / Eq | H6: Sales Rs.Cr. | I6: Beta | J6: Cash and Equivalent
C7: Trent | D7: 3008.95 | E7: 160446.92 | F7: 2561.25 | G7: 0.37 | H7: 20945.44 | I7: 0.79 | J7: 283
C8: Lenskart Solut. | D8: 589.95 | E8: 102575.81 | F8: 3096.6 | G8: 0.35 | H8: 8814.04 | I8: 0.63 | J8: 1543.68
C9: Vedant Fashions | D9: 522 | E9: 12683.46 | F9: 457.59 | G9: 0.23 | H9: 1455.66 | I9: 0.92 | J9: 11.09
C10: A B Lifestyle | D10: 91.48 | E10: 11165.34 | F10: 3018.1 | G10: 2.14 | H10: 8600.97 | I10: 0.88 | J10: 91.51
C11: V2 Retail | D11: 222.9 | E11: 8127.77 | F11: 994.59 | G11: 1.1 | H11: 3060.03 | I11: 0.55 | J11: 128.65
C13: Industry Beta
C15: Name | D15: Equit Value | E15: Total Debt | F15: Debt/Equity | G15: Debt /Capital | H15: Tax Rate % | I15: Levered Beta | J15: Unlivered Beta
C16: Lenskart Solut. | D16: =E8 -> 102575.81 | E16: =F8 -> 3096.6 | F16: =E16/D16 -> 0.030188404 | G16: =E16/(D16+E16) -> 0.02930377 | H16: {=Tax_rate} -> 0.25 | I16: =I8 -> 0.63 | J16: =I16/(1+F16)*(1-H16) -> 0.45865397
C17: Vedant Fashions | D17: =E9 -> 12683.46 | E17: =F9 -> 457.59 | F17: =E17/D17 -> 0.036077695 | G17: =E17/(D17+E17) -> 0.034821418 | H17: {=Tax_rate} -> 0.25 | I17: =I9 -> 0.92 | J17: =I17/(1+F17)*(1-H17) -> 0.66597322
C18: A B Lifestyle | D18: =E10 -> 11165.34 | E18: =F10 -> 3018.1 | F18: =E18/D18 -> 0.27030973 | G18: =E18/(D18+E18) -> 0.21279041 | H18: {=Tax_rate} -> 0.25 | I18: =I10 -> 0.88 | J18: =I18/(1+F18)*(1-H18) -> 0.51955833
C19: V2 Retail | D19: =E11 -> 8127.77 | E19: =F11 -> 994.59 | F19: =E19/D19 -> 0.12236936 | G19: =E19/(D19+E19) -> 0.10902771 | H19: {=Tax_rate} -> 0.25 | I19: =I11 -> 0.55 | J19: =I19/(1+F19)*(1-H19) -> 0.36752607
C20: Average | F20: =AVERAGE(F16:F19) -> 0.1147363 | G20: =AVERAGE(G16:G19) -> 0.096485826 | H20: =AVERAGE(H16:H19) -> 0.25 | I20: =AVERAGE(I16:I19) -> 0.745 | J20: =AVERAGE(J16:J19) -> 0.5029279
C21: Median | F21: =MEDIAN(F16:F19) -> 0.079223527 | G21: =MEDIAN(G16:G19) -> 0.071924563 | H21: =MEDIAN(H16:H19) -> 0.25 | I21: =MEDIAN(I16:I19) -> 0.755 | J21: =MEDIAN(J16:J19) -> 0.48910615
C23: Name | D23: CMP ₹ | E23: Mar Cap ₹ Cr | F23: Debt ₹ Cr | G23: Debt / Eq | H23: Sales ₹ Cr | I23: Beta | J23: Cash & Equivalents ₹ Cr
C24: SBI | D24: 1005.9 | E24: 927686.13 | F24: 6894110.9 | G24: 11.08 | H24: 136240.49 | I24: 1.05 | J24: 212013.35
C25: Union Bank | D25: 186 | E25: 142404.91 | F25: 1370000 | G25: 9.74 | H25: 27427.1 | I25: 1.42 | J25: 43255.93
C26: Punjab National Bank | D26: 116.45 | E26: 133835.31 | F26: 1843390.4 | G26: 11.79 | H26: 33589.17 | I26: 1.24 | J26: 71273.23
C27: Bank of Baroda | D27: 237 | E27: 122458.81 | F27: 1835226.4 | G27: 10.89 | H27: 35114.52 | I27: 1.26 | J27: 50665.14
C28: Indian Bank | D28: 859.9 | E28: 115792.14 | F28: 1230000 | G28: 10.64 | H28: 18095.14 | I28: 1.33 | J28: 31796

Sheet Data Sheet
A1: COMPANY NAME | B1: TRENT LTD | E1: =IF(B2<>B3, "A NEW VERSION OF THE WORKSHEET IS AVAILABLE", "")
A2: LATEST VERSION | B2: 2.1 | E2: PLEASE DO NOT MAKE ANY CHANGES TO THIS SHEET
A3: CURRENT VERSION | B3: 2.1
B4: ='[1]Data Sheet'!B1&" -" -> TRENT LTD -
A5: META
A6: Number of shares | B6: =IF(B9>0, B9/B8, 0) -> 53.32323
A7: Face Value | B7: 1
A8: Current Price | B8: 2997 | C8: =IFERROR('[1]Data Sheet'!C18,'[1]Data Sheet'!C20:C22)*-1 -> -1070.02
A9: Market Capitalization | B9: 159809.72
A15: PROFIT & LOSS
A16: Report Date | B16: 42825 | C16: 43190 | D16: 43555 | E16: 43921 | F16: 44286 | G16: 44651 | H16: 45016 | I16: 45382 | J16: 45747
A17: Sales | B17: 1812.44 | C17: 2157.46 | D17: 2630.24 | E17: 3485.98 | F17: 2592.96 | G17: 4498.02 | H17: 8242.02 | I17: 12375.11 | J17: 17134.61
A18: Raw Material Cost | B18: 911.22 | C18: 1070.02 | D18: 1459.67 | E18: 1951.64 | F18: 1371.64 | G18: 2920.38 | H18: 5211.05 | I18: 7123.6 | J18: 10143.39
A19: Change in Inventory | B19: 29.86 | C19: 38.51 | D19: 148.23 | E19: 69.89 | F19: -162.36 | G19: 438.84 | H19: 491.31 | I19: 164.71 | J19: 454.25
A20: Power and Fuel | B20: 51.28 | C20: 52.75 | D20: 59.18 | E20: 66.64 | F20: 49.41 | G20: 71.89 | H20: 144.28 | I20: 229.16 | J20: 349.87
A21: Other Mfr. Exp | B21: 81.91 | C21: 90.78 | D21: 122.09 | E21: 97.51 | F21: 92 | G21: 127.14 | H21: 211.99 | I21: 264.59 | J21: 369.79
A22: Employee Cost | B22: 194.72 | C22: 233.02 | D22: 288.89 | E22: 361.01 | F22: 303.4 | G22: 402.92 | H22: 659.07 | I22: 1041.74 | J22: 1315.54
A23: Selling and admin | B23: 407.07 | C23: =SUM('Data Sheet'!F18) -> 1371.64 | D23: 514.41 | E23: 436.82 | F23: 364.62 | G23: 705.03 | H23: 1252.53 | I23: 1709.55 | J23: 2322.83
A24: Other Expenses | B24: 62.57 | C24: 90.29 | D24: 93.59 | E24: 113.28 | F24: 135.66 | G24: 114.78 | H24: 140.26 | I24: 200.49 | J24: 267.48
A25: Other Income | B25: 81.31 | C25: 27.47 | D25: 30.14 | E25: 146.63 | F25: 199.4 | G25: 152.16 | H25: 340.6 | I25: 988.91 | J25: 305.06
A26: Depreciation | B26: 41.29 | C26: 45.53 | D26: 51.67 | E26: 247.24 | F26: 257.3 | G26: 310.82 | H26: 493.69 | I26: 671.11 | J26: 895.18
A27: Interest | B27: 45.55 | C27: 43.78 | D27: 50.64 | E27: 263.37 | F27: 260.79 | G27: 324.84 | H27: 408.99 | I27: 367.66 | J27: 200.1
A28: Profit before tax | B28: 128 | C28: 146.66 | D28: 168.47 | E28: 164.99 | F28: -204.82 | G28: 111.22 | H28: 552.07 | I28: 1920.83 | J28: 2029.74
A29: Tax | B29: 43.05 | C29: 59.62 | D29: 73.61 | E29: 59.01 | F29: -23.69 | G29: 76.62 | H29: 158.44 | I29: 443.37 | J29: 495.33
A30: Net profit | B30: 84.86 | C30: 86.97 | D30: 96.96 | E30: 122.85 | F30: -146.17 | G30: 105.83 | H30: 444.63 | I30: 1486.8 | J30: 1546.72
A31: Dividend Amount | B31: 33.23 | C31: 38.21 | D31: 43.2 | E31: 35.55 | F31: 21.33 | G31: 60.44 | H31: 78.21 | I31: 113.76 | J31: 177.75
A40: Quarters
A41: Report Date | B41: 45382 | C41: 45473 | D41: 45565 | E41: 45657 | F41: 45747 | G41: 45838 | H41: 45930 | I41: 46022 | J41: 46112
A42: Sales | B42: 3297.7 | C42: 4104.44 | D42: 4156.67 | E42: 4656.56 | F42: 4216.94 | G42: 4883.48 | H42: 4817.68 | I42: 5345.06 | J42: 5027.99
A43: Expenses | B43: 2828.06 | C43: 3491.09 | D43: 3510.95 | E43: 3809.19 | F43: 3566.03 | G43: 4035.62 | H43: 4001.7 | I43: 4263.99 | J43: 4116.69
A44: Other Income | B44: 694.87 | C44: 100.91 | D44: 51.04 | E44: 79.87 | F44: 74.34 | G44: 49.8 | H44: 27.55 | I44: 4.55 | J44: 27.91
A45: Depreciation | B45: 212.94 | C45: 181.32 | D45: 196.95 | E45: 244.93 | F45: 271.98 | G45: 292.93 | H45: 324.93 | I45: 366.74 | J45: 376.59
A46: Interest | B46: 32.54 | C46: 31.55 | D46: 33 | E46: 36.52 | F46: 37.52 | G46: 40.04 | H46: 41.62 | I46: 42.94 | J46: 43.75
A47: Profit before tax | B47: 919.03 | C47: 501.39 | D47: 466.81 | E47: 645.79 | F47: 415.75 | G47: 564.69 | H47: 476.98 | I47: 675.94 | J47: 518.87
A48: Tax | B48: 206.94 | C48: 110.18 | D48: 131.75 | E48: 149.25 | F48: 104.15 | G48: 139.99 | H48: 103.56 | I48: 165.83 | J48: 105.77
A49: Net profit | B49: 704.23 | C49: 392.57 | D49: 338.75 | E49: 497.25 | F49: 318.15 | G49: 429.69 | H49: 376.86 | I49: 512.77 | J49: 400.33
A50: Operating Profit | B50: 469.64 | C50: 613.35 | D50: 645.72 | E50: 847.37 | F50: 650.91 | G50: 847.86 | H50: 815.98 | I50: 1081.07 | J50: 911.3
A51: EBITDA | B51: 16892.02 | C51: 20164.6 | D51: 19850 | E51: 20404 | F51: 22268 | G51: 23828 | H51: 22359 | I51: 18164 | J51: 17822
A55: BALANCE SHEET
A56: Report Date | B56: 42825 | C56: 43190 | D56: 43555 | E56: 43921 | F56: 44286 | G56: 44651 | H56: 45016 | I56: 45382 | J56: 45747
...
