Workbook
Name Beta: '[1]Simplification>'!$C$5
Name Cost_Of_debt: '[1]Simplify using Name'!$C$9
Name Cost_Of_equity: '[1]Simplify using Name'!$C$7
Name CostofDebt: '[1]Simplification>'!$C$6
Name Current_Sales: '[1]Simplify using Name'!$G$8
Name Debt_Funding: '[1]Simplify using Name'!$C$16
Name Debt_Value: '[1]Simplify using Name'!$C$14
Name DebtValue: '[1]Simplification>'!$C$9
Name Equity_Funding: '[1]Simplify using Name'!$C$15
Name Equity_Value: '[1]Simplify using Name'!$C$13
Name EquityValue: '[1]Simplification>'!$C$8
Name Gross_Margin: '[1]Simplify using Name'!$G$10
Name MarketReturn: '[1]Simplification>'!$C$4
Name Post_Tax_Cost_of_Debt: '[1]Simplify using Name'!$C$11
Name Riskfreerate: '[1]Simplification>'!$C$3
Name Sales_Growth: '[1]Simplify using Name'!$G$9
Name Tax_Rate: '[1]Simplify using Name'!$C$10
Name TAXRate: '[1]Simplification>'!$C$7
Name UPDATE: 'Data Sheet'!$E$1

Sheet Financials>

Sheet HistoricalFS
B2: ="Historical Financial Staement - "&'Data Sheet'!B1 -> Historical Financial Staement - INDIAN BANK
B3: Years | C3: ='Data Sheet'!B16 -> 42825 | D3: ='Data Sheet'!C16 -> 43190 | E3: ='Data Sheet'!D16 -> 43555 | F3: ='Data Sheet'!E16 -> 43921 | G3: ='Data Sheet'!F16 -> 44286 | H3: ='Data Sheet'!G16 -> 44651 | I3: ='Data Sheet'!H16 -> 45016 | J3: ='Data Sheet'!I16 -> 45382 | ... L3: ='Data Sheet'!K16 -> 46112 | M3: LTM
A4: # | B4: Income Statement
B5: Sales | C5: =IFERROR('Data Sheet'!B17,0) -> 16039.22 | D5: =IFERROR('Data Sheet'!C17,0) -> 17115.32 | E5: =IFERROR('Data Sheet'!D17,0) -> 19182.06 | F5: =IFERROR('Data Sheet'!E17,0) -> 21401.28 | G5: =IFERROR('Data Sheet'!F17,0) -> 39108.08 | H5: =IFERROR('Data Sheet'!G17,0) -> 38888.44 | I5: =IFERROR('Data Sheet'!H17,0) -> 44985.16 | J5: =IFERROR('Data Sheet'!I17,0) -> 55649.73 | ... L5: =IFERROR('Data Sheet'!K17,0) -> 67504.09 | M5: =IFERROR(SUM('Data Sheet'!H42:K42),0) -> 69314.13
B6: Sales Growth | C6: - | D6: =D5/C5-1 -> 0.067091791 | E6: =E5/D5-1 -> 0.1207538 | F6: =F5/E5-1 -> 0.11569248 | G6: =G5/F5-1 -> 0.82737107 | H6: =H5/G5-1 -> -0.0056162307 | I6: =I5/H5-1 -> 0.15677461 | J6: =J5/I5-1 -> 0.23706862 | K6: =K5/J5-1 -> 0.11481996 | ... M6: =M5/L5-1 -> 0.026813783
B8: COGS | C8: =IFERROR(SUM('Data Sheet'!B18,'Data Sheet'!B20:B22)-1*'Data Sheet'!B19,0) -> 2089.8 | D8: =IFERROR(SUM('Data Sheet'!C18,'Data Sheet'!C20:C22)-1*'Data Sheet'!C19,0) -> 2200.11 | E8: =IFERROR(SUM('Data Sheet'!D18,'Data Sheet'!D20:D22)-1*'Data Sheet'!D19,0) -> 2323.92 | F8: =IFERROR(SUM('Data Sheet'!E18,'Data Sheet'!E20:E22)-1*'Data Sheet'!E19,0) -> 2573.24 | G8: =IFERROR(SUM('Data Sheet'!F18,'Data Sheet'!F20:F22)-1*'Data Sheet'!F19,0) -> 6614.15 | H8: =IFERROR(SUM('Data Sheet'!G18,'Data Sheet'!G20:G22)-1*'Data Sheet'!G19,0) -> 6985.94 | I8: =IFERROR(SUM('Data Sheet'!H18,'Data Sheet'!H20:H22)-1*'Data Sheet'!H19,0) -> 7775.75 | J8: =IFERROR(SUM('Data Sheet'!I18,'Data Sheet'!I20:I22)-1*'Data Sheet'!I19,0) -> 9574.89 | ... L8: =IFERROR(SUM('Data Sheet'!K18,'Data Sheet'!K20:K22)-1*'Data Sheet'!K19,0) -> 11163.94 | M8: =IFERROR(SUM('Data Sheet'!H43:K43),0) -> 22358.41
B9: COGS % Sales | C9: =C8/C5 -> 0.13029312 | D9: =D8/D5 -> 0.12854624 | E9: =E8/E5 -> 0.1211507 | F9: =F8/F5 -> 0.12023767 | G9: =G8/G5 -> 0.1691249 | H9: =H8/H5 -> 0.17964053 | I9: =I8/I5 -> 0.17285145 | J9: =J8/J5 -> 0.17205636 | ... M9: =M8/M5 -> 0.32256641
B11: Gross Profit | C11: =C5-C8 -> 13949.42 | D11: =D5-D8 -> 14915.21 | E11: =E5-E8 -> 16858.14 | F11: =F5-F8 -> 18828.04 | G11: =G5-G8 -> 32493.93 | H11: =H5-H8 -> 31902.5 | I11: =I5-I8 -> 37209.41 | J11: =J5-J8 -> 46074.84 | ... M11: =M5-M8 -> 46955.72
B12: Gross Profit % Sales | C12: =C11/C5 -> 0.86970688 | D12: =D11/D5 -> 0.87145376 | E12: =E11/E5 -> 0.8788493 | F12: =F11/F5 -> 0.87976233 | G12: =G11/G5 -> 0.8308751 | H12: =H11/H5 -> 0.82035947 | I12: =I11/I5 -> 0.82714855 | J12: =J11/J5 -> 0.82794364 | ... M12: =M11/M5 -> 0.67743359
B14: Selling & General Exp | C14: =IFERROR(SUM('Data Sheet'!B23:B24),0) -> 4053.77 | D14: =IFERROR(SUM('Data Sheet'!C23:C24),0) -> 4798.19 | E14: =IFERROR(SUM('Data Sheet'!D23:D24),0) -> 5964.87 | F14: =IFERROR(SUM('Data Sheet'!E23:E24),0) -> 6664.57 | G14: =IFERROR(SUM('Data Sheet'!F23:F24),0) -> 11414.81 | H14: =IFERROR(SUM('Data Sheet'!G23:G24),0) -> 13298.8 | I14: =IFERROR(SUM('Data Sheet'!H23:H24),0) -> 13801.04 | J14: =IFERROR(SUM('Data Sheet'!I23:I24),0) -> 10767.54 | ... M14: =IFERROR(SUM('Data Sheet'!L23:L24),0) -> 0
B15: S & G Exp % Sales | C15: =C14/C5 -> 0.25274109 | D15: =D14/D5 -> 0.28034474 | E15: =E14/E5 -> 0.31096087 | F15: =F14/F5 -> 0.31140988 | G15: =G14/G5 -> 0.29187856 | H15: =H14/H5 -> 0.34197309 | I15: =I14/I5 -> 0.30679095 | J15: =J14/J5 -> 0.19348773 | ... L15: =L14/L5 -> 0.14141632
B17: EBITDA | C17: =C11-C14 -> 9895.65 | D17: =D11-D14 -> 10117.02 | E17: =E11-E14 -> 10893.27 | F17: =F11-F14 -> 12163.47 | G17: =G11-G14 -> 21079.12 | H17: =H11-H14 -> 18603.7 | I17: =I11-I14 -> 23408.37 | J17: =J11-J14 -> 35307.3 | ... L17: =L11-L14 -> 46793.97 | M17: =IFERROR(SUM('Data Sheet'!H51:K51),0) -> 80458
B18: EBITDA Margins | C18: =C17/C5 -> 0.61696579 | D18: =D17/D5 -> 0.59110902 | E18: =E17/E5 -> 0.56788843 | F18: =F17/F5 -> 0.56835245 | G18: =G17/G5 -> 0.53899654 | H18: =H17/H5 -> 0.47838638 | I18: =I17/I5 -> 0.5203576 | J18: =J17/J5 -> 0.63445591 | ... M18: =M17/M5 -> 1.1607734
B20: Interest | C20: =IFERROR('Data Sheet'!B27,0) -> 10891.46 | D20: =IFERROR('Data Sheet'!C27,0) -> 10851.28 | E20: =IFERROR('Data Sheet'!D27,0) -> 12166.75 | F20: =IFERROR('Data Sheet'!E27,0) -> 13797.51 | G20: =IFERROR('Data Sheet'!F27,0) -> 23438.8 | H20: =IFERROR('Data Sheet'!G27,0) -> 22129.25 | I20: =IFERROR('Data Sheet'!H27,0) -> 24717.29 | J20: =IFERROR('Data Sheet'!I27,0) -> 32340.76 | ... L20: =IFERROR('Data Sheet'!K27,0) -> 40538.66 | M20: =IFERROR(SUM('Data Sheet'!H46:K46),0) -> 41271.43
B21: Interest % Sales | C21: =C20/C5 -> 0.67905172 | D21: =D20/D5 -> 0.63400976 | E21: =E20/E5 -> 0.63427755 | F21: =F20/F5 -> 0.6447049 | G21: =G20/G5 -> 0.59933395 | H21: =H20/H5 -> 0.56904443 | I21: =I20/I5 -> 0.54945431 | J21: =J20/J5 -> 0.58114855 | ... M21: =M20/M5 -> 0.59542593
B23: Depreciation | C23: =IFERROR('Data Sheet'!B26,0) -> 166.24 | D23: =IFERROR('Data Sheet'!C26,0) -> 236.84 | E23: =IFERROR('Data Sheet'!D26,0) -> 259.29 | F23: =IFERROR('Data Sheet'!E26,0) -> 314.01 | G23: =IFERROR('Data Sheet'!F26,0) -> 636.9 | H23: =IFERROR('Data Sheet'!G26,0) -> 600.86 | I23: =IFERROR('Data Sheet'!H26,0) -> 532.39 | J23: =IFERROR('Data Sheet'!I26,0) -> 531.14 | ... L23: =IFERROR('Data Sheet'!K26,0) -> 608.86 | M23: =IFERROR(SUM('Data Sheet'!H45:K45),0) -> 0
B24: Depreciation % Sales | C24: =C23/C5 -> 0.010364594 | D24: =D23/D5 -> 0.013837895 | E24: =E23/E5 -> 0.013517318 | F24: =F23/F5 -> 0.014672487 | G24: =G23/G5 -> 0.016285637 | H24: =H23/H5 -> 0.015450864 | I24: =I23/I5 -> 0.011834792 | J24: =J23/J5 -> 0.009544341 | ... M24: =M23/M5 -> 0
B26: Earning Before Tax | C26: =IFERROR(HistoricalFS!C17-SUM(HistoricalFS!C20,HistoricalFS!C23),0) -> -1162.05 | D26: =IFERROR(HistoricalFS!D17-SUM(HistoricalFS!D20,HistoricalFS!D23),0) -> -971.1 | E26: =IFERROR(HistoricalFS!E17-SUM(HistoricalFS!E20,HistoricalFS!E23),0) -> -1532.77 | F26: =IFERROR(HistoricalFS!F17-SUM(HistoricalFS!F20,HistoricalFS!F23),0) -> -1948.05 | G26: =IFERROR(HistoricalFS!G17-SUM(HistoricalFS!G20,HistoricalFS!G23),0) -> -2996.58 | H26: =IFERROR(HistoricalFS!H17-SUM(HistoricalFS!H20,HistoricalFS!H23),0) -> -4126.41 | I26: =IFERROR(HistoricalFS!I17-SUM(HistoricalFS!I20,HistoricalFS!I23),0) -> -1841.31 | J26: =IFERROR(HistoricalFS!J17-SUM(HistoricalFS!J20,HistoricalFS!J23),0) -> 2435.4 | ... M26: =IFERROR(HistoricalFS!M17-SUM(HistoricalFS!M20,HistoricalFS!M23),0) -> 39186.57
B27: EBT % Sales | C27: =IFERROR(C26/C5,0) -> -0.072450531 | D27: =IFERROR(D26/D5,0) -> -0.056738641 | E27: =IFERROR(E26/E5,0) -> -0.079906433 | F27: =IFERROR(F26/F5,0) -> -0.091024929 | G27: =IFERROR(G26/G5,0) -> -0.076623041 | H27: =IFERROR(H26/H5,0) -> -0.10610891 | I27: =IFERROR(I26/I5,0) -> -0.040931498 | J27: =IFERROR(J26/J5,0) -> 0.043763016 | ... M27: =IFERROR(M26/M5,0) -> 0.5653475
B29: Taxes | C29: =IFERROR('Data Sheet'!B29,0) -> -352.56 | D29: =IFERROR('Data Sheet'!C29,0) -> 182.57 | E29: =IFERROR('Data Sheet'!D29,0) -> 37.74 | F29: =IFERROR('Data Sheet'!E29,0) -> 619.37 | G29: =IFERROR('Data Sheet'!F29,0) -> 99.1 | H29: =IFERROR('Data Sheet'!G29,0) -> -740.59 | I29: =IFERROR('Data Sheet'!H29,0) -> 632.71 | J29: =IFERROR('Data Sheet'!I29,0) -> 2888.2 | ... M29: =IFERROR('Data Sheet'!L29,0) -> 0
B30: Tax % Sales | C30: =C29/C5 -> -0.021981119 | D30: =D29/D5 -> 0.010667052 | E30: =E29/E5 -> 0.0019674633 | F30: =F29/F5 -> 0.028940792 | G30: =G29/G5 -> 0.0025340032 | H30: =H29/H5 -> -0.019043963 | I30: =I29/I5 -> 0.014064861 | J30: =J29/J5 -> 0.051899623 | ... M30: =M29/M5 -> 0
B32: Net Profit | C32: =IFERROR(C26-C29,0) -> -809.49 | D32: =IFERROR(D26-D29,0) -> -1153.67 | E32: =IFERROR(E26-E29,0) -> -1570.51 | F32: =IFERROR(F26-F29,0) -> -2567.42 | G32: =IFERROR(G26-G29,0) -> -3095.68 | H32: =IFERROR(H26-H29,0) -> -3385.82 | I32: =IFERROR(I26-I29,0) -> -2474.02 | J32: =IFERROR(J26-J29,0) -> -452.8 | ... M32: =IFERROR(M26-M29,0) -> 39186.57
B33: Net Margin | C33: =C32/C5 -> -0.050469412 | D33: =D32/D5 -> -0.067405693 | E33: =E32/E5 -> -0.081873897 | F33: =F32/F5 -> -0.11996572 | G33: =G32/G5 -> -0.079157044 | H33: =H32/H5 -> -0.087064948 | I33: =I32/I5 -> -0.054996359 | J33: =J32/J5 -> -0.0081366073 | ... M33: =M32/M5 -> 0.5653475
B35: No.of Equity Shares | C35: =IFERROR('Data Sheet'!B93,0) -> 48.03 | D35: =IFERROR('Data Sheet'!C93,0) -> 48.03 | E35: =IFERROR('Data Sheet'!D93,0) -> 48.03 | F35: =IFERROR('Data Sheet'!E93,0) -> 60.88 | G35: =IFERROR('Data Sheet'!F93,0) -> 112.94 | H35: =IFERROR('Data Sheet'!G93,0) -> 124.54 | I35: =IFERROR('Data Sheet'!H93,0) -> 124.54 | J35: =IFERROR('Data Sheet'!I93,0) -> 134.7 | ... M35: =IFERROR('Data Sheet'!L93,0) -> 0
B37: EPS | C37: =IFERROR(C32/C35,0) -> -16.853841 | D37: =IFERROR(D32/D35,0) -> -24.019779 | E37: =IFERROR(E32/E35,0) -> -32.698522 | F37: =IFERROR(F32/F35,0) -> -42.171813 | G37: =IFERROR(G32/G35,0) -> -27.409952 | H37: =IFERROR(H32/H35,0) -> -27.186607 | I37: =IFERROR(I32/I35,0) -> -19.865264 | J37: =IFERROR(J32/J35,0) -> -3.3615442 | ... M37: =IFERROR(M32/M35,0) -> 0
B38: EPS % Growth | C38: =C37/C37-1 -> 0 | D38: =D37/C37-1 -> 0.42518129 | E38: =E37/D37-1 -> 0.36131649 | F38: =F37/E37-1 -> 0.28971621 | G38: =G37/F37-1 -> -0.35004094 | H38: =H37/G37-1 -> -0.0081483351 | I38: =I37/H37-1 -> -0.26929961 | J38: =J37/I37-1 -> -0.83078281 | K38: =K37/J37-1 -> -3.171864 | ... M38: =M37/L37-1 -> -1
B40: Dividend Per Share | C40: =IFERROR('Data Sheet'!B31/HistoricalFS!C35,0) -> 5.9997918 | D40: =IFERROR('Data Sheet'!C31/HistoricalFS!D35,0) -> 0 | E40: =IFERROR('Data Sheet'!D31/HistoricalFS!E35,0) -> 0 | F40: =IFERROR('Data Sheet'!E31/HistoricalFS!F35,0) -> 0 | G40: =IFERROR('Data Sheet'!F31/HistoricalFS!G35,0) -> 1.9999115 | H40: =IFERROR('Data Sheet'!G31/HistoricalFS!H35,0) -> 6.5002409 | I40: =IFERROR('Data Sheet'!H31/HistoricalFS!I35,0) -> 8.6002891 | J40: =IFERROR('Data Sheet'!I31/HistoricalFS!J35,0) -> 11.999629 | ... M40: =IFERROR('Data Sheet'!L31/HistoricalFS!M35,0) -> 0
B41: Dividend Per Share | C41: =IFERROR(IF(C37>C40,1-C38,0),0) -> 0 | D41: =IFERROR(IF(D37>D40,1-D38,0),0) -> 0 | E41: =IFERROR(IF(E37>E40,1-E38,0),0) -> 0 | F41: =IFERROR(IF(F37>F40,1-F38,0),0) -> 0 | G41: =IFERROR(IF(G37>G40,1-G38,0),0) -> 0 | H41: =IFERROR(IF(H37>H40,1-H38,0),0) -> 0 | I41: =IFERROR(IF(I37>I40,1-I38,0),0) -> 0 | J41: =IFERROR(IF(J37>J40,1-J38,0),0) -> 0 | ... M41: =IFERROR(IF(M37>M40,1-M38,0),0) -> 0
B43: Retained Earning | C43: =IFERROR(1-C41,0) -> 1 | D43: =IFERROR(1-D41,0) -> 1 | E43: =IFERROR(1-E41,0) -> 1 | F43: =IFERROR(1-F41,0) -> 1 | G43: =IFERROR(1-G41,0) -> 1 | H43: =IFERROR(1-H41,0) -> 1 | I43: =IFERROR(1-I41,0) -> 1 | J43: =IFERROR(1-J41,0) -> 1 | ... M43: =IFERROR(1-M41,0) -> 1
A46: # | B46: Balance Sheet
B47: Equity Share Capital | C47: =IFERROR('Data Sheet'!B57,0) -> 480.29 | D47: =IFERROR('Data Sheet'!C57,0) -> 480.29 | E47: =IFERROR('Data Sheet'!D57,0) -> 480.29 | F47: =IFERROR('Data Sheet'!E57,0) -> 608.8 | G47: =IFERROR('Data Sheet'!F57,0) -> 1129.37 | H47: =IFERROR('Data Sheet'!G57,0) -> 1245.44 | I47: =IFERROR('Data Sheet'!H57,0) -> 1245.44 | J47: =IFERROR('Data Sheet'!I57,0) -> 1346.96 | ... L47: =IFERROR('Data Sheet'!K57,0) -> 1346.96
B48: Reserves | C48: =IFERROR('Data Sheet'!B58,0) -> 16953.55 | D48: =IFERROR('Data Sheet'!C58,0) -> 18235.15 | E48: =IFERROR('Data Sheet'!D58,0) -> 19235.17 | F48: =IFERROR('Data Sheet'!E58,0) -> 22158.78 | G48: =IFERROR('Data Sheet'!F58,0) -> 38328.7 | H48: =IFERROR('Data Sheet'!G58,0) -> 43706.49 | I48: =IFERROR('Data Sheet'!H58,0) -> 48261.38 | J48: =IFERROR('Data Sheet'!I58,0) -> 58901.24 | ... L48: =IFERROR('Data Sheet'!K58,0) -> 78695.92
B49: Borrowings | C49: =IFERROR('Data Sheet'!B59,0) -> 195116.93 | D49: =IFERROR('Data Sheet'!C59,0) -> 228021.98 | E49: =IFERROR('Data Sheet'!D59,0) -> 254178.34 | F49: =IFERROR('Data Sheet'!E59,0) -> 281014.71 | G49: =IFERROR('Data Sheet'!F59,0) -> 562792.57 | H49: =IFERROR('Data Sheet'!G59,0) -> 610788.4 | I49: =IFERROR('Data Sheet'!H59,0) -> 643215.65 | J49: =IFERROR('Data Sheet'!I59,0) -> 711095.95 | ... L49: =IFERROR('Data Sheet'!K59,0) -> 874460.58
B50: Other Liabilities | C50: =IFERROR('Data Sheet'!B60,0) -> 5956.67 | D50: =IFERROR('Data Sheet'!C60,0) -> 6243.99 | E50: =IFERROR('Data Sheet'!D60,0) -> 6494.48 | F50: =IFERROR('Data Sheet'!E60,0) -> 6358.67 | G50: =IFERROR('Data Sheet'!F60,0) -> 23284.53 | H50: =IFERROR('Data Sheet'!G60,0) -> 18356.1 | I50: =IFERROR('Data Sheet'!H60,0) -> 20611.53 | J50: =IFERROR('Data Sheet'!I60,0) -> 24364.67 | ... L50: =IFERROR('Data Sheet'!K60,0) -> 37049.33
B51: Total Liability | C51: =SUM(C47:C50) -> 218507.44 | D51: =SUM(D47:D50) -> 252981.41 | E51: =SUM(E47:E50) -> 280388.28 | F51: =SUM(F47:F50) -> 310140.96 | G51: =SUM(G47:G50) -> 625535.17 | H51: =SUM(H47:H50) -> 674096.43 | I51: =SUM(I47:I50) -> 713334 | J51: =SUM(J47:J50) -> 795708.82 | ... L51: =SUM(L47:L50) -> 991552.79
B53: Fixed Asset Net Block | C53: =IFERROR('Data Sheet'!B62,0) -> 3436.04 | D53: =IFERROR('Data Sheet'!C62,0) -> 3421.47 | E53: =IFERROR('Data Sheet'!D62,0) -> 3964.23 | F53: =IFERROR('Data Sheet'!E62,0) -> 3898.3 | G53: =IFERROR('Data Sheet'!F62,0) -> 7392.13 | H53: =IFERROR('Data Sheet'!G62,0) -> 7693.78 | I53: =IFERROR('Data Sheet'!H62,0) -> 7471.6 | J53: =IFERROR('Data Sheet'!I62,0) -> 7537.62 | ... L53: =IFERROR('Data Sheet'!K62,0) -> 8674
B54: Capital Work in Progress | C54: =IFERROR('Data Sheet'!B63,0) -> 10.64 | D54: =IFERROR('Data Sheet'!C63,0) -> 0.61 | E54: =IFERROR('Data Sheet'!D63,0) -> 0.76 | F54: =IFERROR('Data Sheet'!E63,0) -> 0.78 | G54: =IFERROR('Data Sheet'!F63,0) -> 0.43 | H54: =IFERROR('Data Sheet'!G63,0) -> 5.13 | I54: =IFERROR('Data Sheet'!H63,0) -> 9.07 | J54: =IFERROR('Data Sheet'!I63,0) -> 2.28 | ... L54: =IFERROR('Data Sheet'!K63,0) -> 2.81
B55: Investments | C55: =IFERROR('Data Sheet'!B64,0) -> 67781.19 | D55: =IFERROR('Data Sheet'!C64,0) -> 71619.14 | E55: =IFERROR('Data Sheet'!D64,0) -> 65271.55 | F55: =IFERROR('Data Sheet'!E64,0) -> 81871.16 | G55: =IFERROR('Data Sheet'!F64,0) -> 178292.44 | H55: =IFERROR('Data Sheet'!G64,0) -> 176501.61 | I55: =IFERROR('Data Sheet'!H64,0) -> 188366.28 | J55: =IFERROR('Data Sheet'!I64,0) -> 215241.82 | ... L55: =IFERROR('Data Sheet'!K64,0) -> 247682.04
B56: Other Assets | C56: =IFERROR('Data Sheet'!B65-SUM('Data Sheet'!B67:B69),0) -> 141690.87 | D56: =IFERROR('Data Sheet'!C65-SUM('Data Sheet'!C67:C69),0) -> 167438.59 | E56: =IFERROR('Data Sheet'!D65-SUM('Data Sheet'!D67:D69),0) -> 199449.87 | F56: =IFERROR('Data Sheet'!E65-SUM('Data Sheet'!E67:E69),0) -> 218634.6 | G56: =IFERROR('Data Sheet'!F65-SUM('Data Sheet'!F67:F69),0) -> 412304.99 | H56: =IFERROR('Data Sheet'!G65-SUM('Data Sheet'!G67:G69),0) -> 431341.25 | I56: =IFERROR('Data Sheet'!H65-SUM('Data Sheet'!H67:H69),0) -> 484794.32 | J56: =IFERROR('Data Sheet'!I65-SUM('Data Sheet'!I67:I69),0) -> 540224.34 | ... L56: =IFERROR('Data Sheet'!K65-SUM('Data Sheet'!K67:K69),0) -> 701139.02
B57: Total Non Current Asset | C57: =SUM(C53:C56) -> 212918.74 | D57: =SUM(D53:D56) -> 242479.81 | E57: =SUM(E53:E56) -> 268686.41 | F57: =SUM(F53:F56) -> 304404.84 | G57: =SUM(G53:G56) -> 597989.99 | H57: =SUM(H53:H56) -> 615541.77 | I57: =SUM(I53:I56) -> 680641.27 | J57: =SUM(J53:J56) -> 763006.06 | ... L57: =SUM(L53:L56) -> 957497.87
...

Sheet Ratio Analysis
B2: ="Ratio Analysis Staement - "&'Data Sheet'!B1 -> Ratio Analysis Staement - INDIAN BANK
B3: Years | C3: ='Data Sheet'!B16 -> 42825 | D3: ='Data Sheet'!C16 -> 43190 | E3: ='Data Sheet'!D16 -> 43555 | F3: ='Data Sheet'!E16 -> 43921 | G3: ='Data Sheet'!F16 -> 44286 | H3: ='Data Sheet'!G16 -> 44651 | I3: ='Data Sheet'!H16 -> 45016 | J3: ='Data Sheet'!I16 -> 45382 | ... L3: ='Data Sheet'!K16 -> 46112 | M3: Trend | N3: Mean | O3: Median
B5: Sales Growth | D5: =IFERROR(HistoricalFS!D6,0) -> 0.067091791 | E5: =IFERROR(HistoricalFS!E6,0) -> 0.1207538 | F5: =IFERROR(HistoricalFS!F6,0) -> 0.11569248 | G5: =IFERROR(HistoricalFS!G6,0) -> 0.82737107 | H5: =IFERROR(HistoricalFS!H6,0) -> -0.0056162307 | I5: =IFERROR(HistoricalFS!I6,0) -> 0.15677461 | J5: =IFERROR(HistoricalFS!J6,0) -> 0.23706862 | K5: =IFERROR(HistoricalFS!K6,0) -> 0.11481996 | L5: =IFERROR(HistoricalFS!L6,0) -> 0.088083659 | N5: =IFERROR(AVERAGE(D5:L5),0) -> 0.19133775 | O5: =IFERROR(MEDIAN(C5:L5),0) -> 0.11569248
B6: EBITDA Growth | D6: =IFERROR(HistoricalFS!D17/HistoricalFS!C17-1,0) -> 0.022370435 | E6: =IFERROR(HistoricalFS!E17/HistoricalFS!D17-1,0) -> 0.076727139 | F6: =IFERROR(HistoricalFS!F17/HistoricalFS!E17-1,0) -> 0.11660411 | G6: =IFERROR(HistoricalFS!G17/HistoricalFS!F17-1,0) -> 0.73298574 | H6: =IFERROR(HistoricalFS!H17/HistoricalFS!G17-1,0) -> -0.11743469 | I6: =IFERROR(HistoricalFS!I17/HistoricalFS!H17-1,0) -> 0.25826422 | J6: =IFERROR(HistoricalFS!J17/HistoricalFS!I17-1,0) -> 0.50831946 | K6: =IFERROR(HistoricalFS!K17/HistoricalFS!J17-1,0) -> 0.19582211 | L6: =IFERROR(HistoricalFS!L17/HistoricalFS!K17-1,0) -> 0.10830376 | N6: =IFERROR(AVERAGE(D6:L6),0) -> 0.21132914 | O6: =IFERROR(MEDIAN(C6:L6),0) -> 0.11660411
B7: EBT Growth | D7: =IFERROR(HistoricalFS!D26/HistoricalFS!C26-1,0) -> -0.16432167 | E7: =IFERROR(HistoricalFS!E26/HistoricalFS!D26-1,0) -> 0.57838534 | F7: =IFERROR(HistoricalFS!F26/HistoricalFS!E26-1,0) -> 0.27093432 | G7: =IFERROR(HistoricalFS!G26/HistoricalFS!F26-1,0) -> 0.53824594 | H7: =IFERROR(HistoricalFS!H26/HistoricalFS!G26-1,0) -> 0.37703983 | I7: =IFERROR(HistoricalFS!I26/HistoricalFS!H26-1,0) -> -0.55377435 | J7: =IFERROR(HistoricalFS!J26/HistoricalFS!I26-1,0) -> -2.3226453 | K7: =IFERROR(HistoricalFS!K26/HistoricalFS!J26-1,0) -> 0.99230517 | L7: =IFERROR(HistoricalFS!L26/HistoricalFS!K26-1,0) -> 0.16372221 | N7: =IFERROR(AVERAGE(D7:L7),0) -> -0.01334539 | O7: =IFERROR(MEDIAN(C7:L7),0) -> 0.27093432
B8: Net Profit Growth | D8: =IFERROR(HistoricalFS!D32/HistoricalFS!C32-1,0) -> 0.42518129 | E8: =IFERROR(HistoricalFS!E32/HistoricalFS!D32-1,0) -> 0.36131649 | F8: =IFERROR(HistoricalFS!F32/HistoricalFS!E32-1,0) -> 0.63476832 | G8: =IFERROR(HistoricalFS!G32/HistoricalFS!F32-1,0) -> 0.20575519 | H8: =IFERROR(HistoricalFS!H32/HistoricalFS!G32-1,0) -> 0.093724158 | I8: =IFERROR(HistoricalFS!I32/HistoricalFS!H32-1,0) -> -0.26929961 | J8: =IFERROR(HistoricalFS!J32/HistoricalFS!I32-1,0) -> -0.81697804 | K8: =IFERROR(HistoricalFS!K32/HistoricalFS!J32-1,0) -> -3.171864 | L8: =IFERROR(HistoricalFS!L32/HistoricalFS!K32-1,0) -> 0.42195603 | N8: =IFERROR(AVERAGE(D8:L8),0) -> -0.2350489 | O8: =IFERROR(MEDIAN(C8:L8),0) -> 0.20575519
B9: Dividend Growth | D9: =IFERROR(HistoricalFS!D40/HistoricalFS!C40-1,0) -> -1 | E9: =IFERROR(HistoricalFS!E40/HistoricalFS!D40-1,0) -> 0 | F9: =IFERROR(HistoricalFS!F40/HistoricalFS!E40-1,0) -> 0 | G9: =IFERROR(HistoricalFS!G40/HistoricalFS!F40-1,0) -> 0 | H9: =IFERROR(HistoricalFS!H40/HistoricalFS!G40-1,0) -> 2.2502643 | I9: =IFERROR(HistoricalFS!I40/HistoricalFS!H40-1,0) -> 0.32307236 | J9: =IFERROR(HistoricalFS!J40/HistoricalFS!I40-1,0) -> 0.39525878 | K9: =IFERROR(HistoricalFS!K40/HistoricalFS!J40-1,0) -> 0.35416834 | L9: =IFERROR(HistoricalFS!L40/HistoricalFS!K40-1,0) -> 0.12307601 | N9: =IFERROR(AVERAGE(D9:L9),0) -> 0.27175998 | O9: =IFERROR(MEDIAN(C9:L9),0) -> 0.12307601
B11: Gross Margin | C11: =IFERROR(HistoricalFS!C12,0) -> 0.86970688 | D11: =IFERROR(HistoricalFS!D12,0) -> 0.87145376 | E11: =IFERROR(HistoricalFS!E12,0) -> 0.8788493 | F11: =IFERROR(HistoricalFS!F12,0) -> 0.87976233 | G11: =IFERROR(HistoricalFS!G12,0) -> 0.8308751 | H11: =IFERROR(HistoricalFS!H12,0) -> 0.82035947 | I11: =IFERROR(HistoricalFS!I12,0) -> 0.82714855 | J11: =IFERROR(HistoricalFS!J12,0) -> 0.82794364 | ... L11: =IFERROR(HistoricalFS!L12,0) -> 0.83461832 | N11: =IFERROR(AVERAGE(D11:L11),0) -> 0.84508614 | O11: =IFERROR(MEDIAN(C11:L11),0) -> 0.83469154
B12: EBITDA Margin | C12: =IFERROR(HistoricalFS!C18,0) -> 0.61696579 | D12: =IFERROR(HistoricalFS!D18,0) -> 0.59110902 | E12: =IFERROR(HistoricalFS!E18,0) -> 0.56788843 | F12: =IFERROR(HistoricalFS!F18,0) -> 0.56835245 | G12: =IFERROR(HistoricalFS!G18,0) -> 0.53899654 | H12: =IFERROR(HistoricalFS!H18,0) -> 0.47838638 | I12: =IFERROR(HistoricalFS!I18,0) -> 0.5203576 | J12: =IFERROR(HistoricalFS!J18,0) -> 0.63445591 | ... L12: =IFERROR(HistoricalFS!L18,0) -> 0.693202 | N12: =IFERROR(AVERAGE(D12:L12),0) -> 0.5859226 | O12: =IFERROR(MEDIAN(C12:L12),0) -> 0.57973074
B13: EBIT Margin | C13: =IFERROR((HistoricalFS!C17-HistoricalFS!C23)/HistoricalFS!C5,0) -> 0.60660119 | D13: =IFERROR((HistoricalFS!D17-HistoricalFS!D23)/HistoricalFS!D5,0) -> 0.57727112 | E13: =IFERROR((HistoricalFS!E17-HistoricalFS!E23)/HistoricalFS!E5,0) -> 0.55437112 | F13: =IFERROR((HistoricalFS!F17-HistoricalFS!F23)/HistoricalFS!F5,0) -> 0.55367997 | G13: =IFERROR((HistoricalFS!G17-HistoricalFS!G23)/HistoricalFS!G5,0) -> 0.52271091 | H13: =IFERROR((HistoricalFS!H17-HistoricalFS!H23)/HistoricalFS!H5,0) -> 0.46293552 | I13: =IFERROR((HistoricalFS!I17-HistoricalFS!I23)/HistoricalFS!I5,0) -> 0.50852281 | J13: =IFERROR((HistoricalFS!J17-HistoricalFS!J23)/HistoricalFS!J5,0) -> 0.62491157 | ... L13: =IFERROR((HistoricalFS!L17-HistoricalFS!L23)/HistoricalFS!L5,0) -> 0.6841824 | N13: =IFERROR(AVERAGE(D13:L13),0) -> 0.57337655 | O13: =IFERROR(MEDIAN(C13:L13),0) -> 0.56582112
B14: EBT Margin | C14: =IFERROR(HistoricalFS!C27,0) -> -0.072450531 | D14: =IFERROR(HistoricalFS!D27,0) -> -0.056738641 | E14: =IFERROR(HistoricalFS!E27,0) -> -0.079906433 | F14: =IFERROR(HistoricalFS!F27,0) -> -0.091024929 | G14: =IFERROR(HistoricalFS!G27,0) -> -0.076623041 | H14: =IFERROR(HistoricalFS!H27,0) -> -0.10610891 | I14: =IFERROR(HistoricalFS!I27,0) -> -0.040931498 | J14: =IFERROR(HistoricalFS!J27,0) -> 0.043763016 | ... L14: =IFERROR(HistoricalFS!L27,0) -> 0.083646043 | N14: =IFERROR(AVERAGE(D14:L14),0) -> -0.027301678 | O14: =IFERROR(MEDIAN(C14:L14),0) -> -0.064594586
B15: Net Profit Margin | C15: =IFERROR(HistoricalFS!C33,0) -> -0.050469412 | D15: =IFERROR(HistoricalFS!D33,0) -> -0.067405693 | E15: =IFERROR(HistoricalFS!E33,0) -> -0.081873897 | F15: =IFERROR(HistoricalFS!F33,0) -> -0.11996572 | G15: =IFERROR(HistoricalFS!G33,0) -> -0.079157044 | H15: =IFERROR(HistoricalFS!H33,0) -> -0.087064948 | I15: =IFERROR(HistoricalFS!I33,0) -> -0.054996359 | J15: =IFERROR(HistoricalFS!J33,0) -> -0.0081366073 | ... L15: =IFERROR(HistoricalFS!L33,0) -> 0.020715486 | N15: =IFERROR(AVERAGE(D15:L15),0) -> -0.051337028 | O15: =IFERROR(MEDIAN(C15:L15),0) -> -0.061201026
B17: Sales Expenses% sales | C17: =IFERROR(HistoricalFS!C15,0) -> 0.25274109 | D17: =IFERROR(HistoricalFS!D15,0) -> 0.28034474 | E17: =IFERROR(HistoricalFS!E15,0) -> 0.31096087 | F17: =IFERROR(HistoricalFS!F15,0) -> 0.31140988 | G17: =IFERROR(HistoricalFS!G15,0) -> 0.29187856 | H17: =IFERROR(HistoricalFS!H15,0) -> 0.34197309 | I17: =IFERROR(HistoricalFS!I15,0) -> 0.30679095 | J17: =IFERROR(HistoricalFS!J15,0) -> 0.19348773 | ... L17: =IFERROR(HistoricalFS!L15,0) -> 0.14141632 | N17: =IFERROR(AVERAGE(C17:L17),0) -> 0.25852129 | O17: =IFERROR(MEDIAN(C17:L17),0) -> 0.28611165
B18: Depreciation%sales | C18: =IFERROR(HistoricalFS!C24,0) -> 0.010364594 | D18: =IFERROR(HistoricalFS!D24,0) -> 0.013837895 | E18: =IFERROR(HistoricalFS!E24,0) -> 0.013517318 | F18: =IFERROR(HistoricalFS!F24,0) -> 0.014672487 | G18: =IFERROR(HistoricalFS!G24,0) -> 0.016285637 | H18: =IFERROR(HistoricalFS!H24,0) -> 0.015450864 | I18: =IFERROR(HistoricalFS!I24,0) -> 0.011834792 | J18: =IFERROR(HistoricalFS!J24,0) -> 0.009544341 | ... L18: =IFERROR(HistoricalFS!L24,0) -> 0.0090196016 | N18: =IFERROR(AVERAGE(C18:L18),0) -> 0.012327906 | O18: =IFERROR(MEDIAN(C18:L18),0) -> 0.012676055
B19: Operating Income % Sales | C19: =IFERROR(C13,0) -> 0.60660119 | D19: =IFERROR(D13,0) -> 0.57727112 | E19: =IFERROR(E13,0) -> 0.55437112 | F19: =IFERROR(F13,0) -> 0.55367997 | G19: =IFERROR(G13,0) -> 0.52271091 | H19: =IFERROR(H13,0) -> 0.46293552 | I19: =IFERROR(I13,0) -> 0.50852281 | J19: =IFERROR(J13,0) -> 0.62491157 | ... L19: =IFERROR(L13,0) -> 0.6841824 | N19: =IFERROR(AVERAGE(C19:L19),0) -> 0.57669902 | O19: =IFERROR(MEDIAN(C19:L19),0) -> 0.56582112
B21: Return On Capital Employed | C21: =IFERROR((HistoricalFS!C17-HistoricalFS!C23)/SUM(HistoricalFS!C47:C49),0) -> 0.045774522 | D21: =IFERROR((HistoricalFS!D17-HistoricalFS!D23)/SUM(HistoricalFS!D47:D49),0) -> 0.040043298 | E21: =IFERROR((HistoricalFS!E17-HistoricalFS!E23)/SUM(HistoricalFS!E47:E49),0) -> 0.038825194 | F21: =IFERROR((HistoricalFS!F17-HistoricalFS!F23)/SUM(HistoricalFS!F47:F49),0) -> 0.039006421 | G21: =IFERROR((HistoricalFS!G17-HistoricalFS!G23)/SUM(HistoricalFS!G47:G49),0) -> 0.033943044 | H21: =IFERROR((HistoricalFS!H17-HistoricalFS!H23)/SUM(HistoricalFS!H47:H49),0) -> 0.027454221 | I21: =IFERROR((HistoricalFS!I17-HistoricalFS!I23)/SUM(HistoricalFS!I47:I49),0) -> 0.033023297 | J21: =IFERROR((HistoricalFS!J17-HistoricalFS!J23)/SUM(HistoricalFS!J47:J49),0) -> 0.045085141 | ... L21: =IFERROR((HistoricalFS!L17-HistoricalFS!L23)/SUM(HistoricalFS!L47:L49),0) -> 0.04838653 | N21: =IFERROR(AVERAGE(C21:L21),0) -> 0.040056554 | O21: =IFERROR(MEDIAN(C21:L21),0) -> 0.03952486
B22: Retained Earning% | C22: =IFERROR(HistoricalFS!C43,0) -> 1 | D22: =IFERROR(HistoricalFS!D43,0) -> 1 | E22: =IFERROR(HistoricalFS!E43,0) -> 1 | F22: =IFERROR(HistoricalFS!F43,0) -> 1 | G22: =IFERROR(HistoricalFS!G43,0) -> 1 | H22: =IFERROR(HistoricalFS!H43,0) -> 1 | I22: =IFERROR(HistoricalFS!I43,0) -> 1 | J22: =IFERROR(HistoricalFS!J43,0) -> 1 | ... L22: =IFERROR(HistoricalFS!L43,0) -> 1 | N22: =IFERROR(AVERAGE(C22:L22),0) -> 1 | O22: =IFERROR(MEDIAN(C22:L22),0) -> 1
B23: Return On Equity% | C23: =IFERROR(HistoricalFS!C32/SUM(HistoricalFS!C47:C48),0) -> -0.046432111 | D23: =IFERROR(HistoricalFS!D32/SUM(HistoricalFS!D47:D48),0) -> -0.061642686 | E23: =IFERROR(HistoricalFS!E32/SUM(HistoricalFS!E47:E48),0) -> -0.079658806 | F23: =IFERROR(HistoricalFS!F32/SUM(HistoricalFS!F47:F48),0) -> -0.11276649 | G23: =IFERROR(HistoricalFS!G32/SUM(HistoricalFS!G47:G48),0) -> -0.078454927 | H23: =IFERROR(HistoricalFS!H32/SUM(HistoricalFS!H47:H48),0) -> -0.075320904 | I23: =IFERROR(HistoricalFS!I32/SUM(HistoricalFS!I47:I48),0) -> -0.049973317 | J23: =IFERROR(HistoricalFS!J32/SUM(HistoricalFS!J47:J48),0) -> -0.0075155772 | ... L23: =IFERROR(HistoricalFS!L32/SUM(HistoricalFS!L47:L48),0) -> 0.017470386 | N23: =IFERROR(AVERAGE(C23:L23),0) -> -0.048054279 | O23: =IFERROR(MEDIAN(C23:L23),0) -> -0.055808002
B24: Self Sustained Growth Rate | C24: =IFERROR(C22*C23,0) -> -0.046432111 | D24: =IFERROR(D22*D23,0) -> -0.061642686 | E24: =IFERROR(E22*E23,0) -> -0.079658806 | F24: =IFERROR(F22*F23,0) -> -0.11276649 | G24: =IFERROR(G22*G23,0) -> -0.078454927 | H24: =IFERROR(H22*H23,0) -> -0.075320904 | I24: =IFERROR(I22*I23,0) -> -0.049973317 | J24: =IFERROR(J22*J23,0) -> -0.0075155772 | ... L24: =IFERROR(L22*L23,0) -> 0.017470386 | N24: =IFERROR(AVERAGE(C24:L24),0) -> -0.048054279 | O24: =IFERROR(MEDIAN(C24:L24),0) -> -0.055808002
B25: Interest Coverage Ratio | C25: =IFERROR((HistoricalFS!C17-HistoricalFS!C23)/HistoricalFS!C20,0) -> 0.89330632 | D25: =IFERROR((HistoricalFS!D17-HistoricalFS!D23)/HistoricalFS!D20,0) -> 0.91050825 | E25: =IFERROR((HistoricalFS!E17-HistoricalFS!E23)/HistoricalFS!E20,0) -> 0.87401977 | F25: =IFERROR((HistoricalFS!F17-HistoricalFS!F23)/HistoricalFS!F20,0) -> 0.85881148 | G25: =IFERROR((HistoricalFS!G17-HistoricalFS!G23)/HistoricalFS!G20,0) -> 0.87215301 | H25: =IFERROR((HistoricalFS!H17-HistoricalFS!H23)/HistoricalFS!H20,0) -> 0.81353141 | I25: =IFERROR((HistoricalFS!I17-HistoricalFS!I23)/HistoricalFS!I20,0) -> 0.92550518 | J25: =IFERROR((HistoricalFS!J17-HistoricalFS!J23)/HistoricalFS!J20,0) -> 1.0753044 | ... L25: =IFERROR((HistoricalFS!L17-HistoricalFS!L23)/HistoricalFS!L20,0) -> 1.1392856 | N25: =IFERROR(AVERAGE(C25:L25),0) -> 0.94941808 | O25: =IFERROR(MEDIAN(C25:L25),0) -> 0.90190728
B27: Debtor Turnover Ratio | C27: =IFERROR(HistoricalFS!C5/HistoricalFS!C59,0) -> 0 | D27: =IFERROR(HistoricalFS!D5/HistoricalFS!D59,0) -> 0 | E27: =IFERROR(HistoricalFS!E5/HistoricalFS!E59,0) -> 0 | F27: =IFERROR(HistoricalFS!F5/HistoricalFS!F59,0) -> 0 | G27: =IFERROR(HistoricalFS!G5/HistoricalFS!G59,0) -> 0 | H27: =IFERROR(HistoricalFS!H5/HistoricalFS!H59,0) -> 0 | I27: =IFERROR(HistoricalFS!I5/HistoricalFS!I59,0) -> 0 | J27: =IFERROR(HistoricalFS!J5/HistoricalFS!J59,0) -> 0 | ... L27: =IFERROR(HistoricalFS!L5/HistoricalFS!L59,0) -> 0 | N27: =IFERROR(AVERAGE(C27:L27),0) -> 0 | O27: =IFERROR(MEDIAN(C27:L27),0) -> 0
B28: Creditor Turnover Ratio | C28: =IFERROR(HistoricalFS!C5/HistoricalFS!C50,0) -> 2.6926487 | D28: =IFERROR(HistoricalFS!D5/HistoricalFS!D50,0) -> 2.741087 | E28: =IFERROR(HistoricalFS!E5/HistoricalFS!E50,0) -> 2.9535944 | F28: =IFERROR(HistoricalFS!F5/HistoricalFS!F50,0) -> 3.365685 | G28: =IFERROR(HistoricalFS!G5/HistoricalFS!G50,0) -> 1.6795735 | H28: =IFERROR(HistoricalFS!H5/HistoricalFS!H50,0) -> 2.1185568 | I28: =IFERROR(HistoricalFS!I5/HistoricalFS!I50,0) -> 2.1825241 | J28: =IFERROR(HistoricalFS!J5/HistoricalFS!J50,0) -> 2.2840338 | ... L28: =IFERROR(HistoricalFS!L5/HistoricalFS!L50,0) -> 1.8220057 | N28: =IFERROR(AVERAGE(C28:L28),0) -> 2.4148147 | O28: =IFERROR(MEDIAN(C28:L28),0) -> 2.2962359
B29: Inventory Turnover Ratio | C29: =IFERROR(HistoricalFS!C5/HistoricalFS!C60,0) -> 0 | D29: =IFERROR(HistoricalFS!D5/HistoricalFS!D60,0) -> 0 | E29: =IFERROR(HistoricalFS!E5/HistoricalFS!E60,0) -> 0 | F29: =IFERROR(HistoricalFS!F5/HistoricalFS!F60,0) -> 0 | G29: =IFERROR(HistoricalFS!G5/HistoricalFS!G60,0) -> 0 | H29: =IFERROR(HistoricalFS!H5/HistoricalFS!H60,0) -> 0 | I29: =IFERROR(HistoricalFS!I5/HistoricalFS!I60,0) -> 0 | J29: =IFERROR(HistoricalFS!J5/HistoricalFS!J60,0) -> 0 | ... L29: =IFERROR(HistoricalFS!L5/HistoricalFS!L60,0) -> 0 | N29: =IFERROR(AVERAGE(C29:L29),0) -> 0 | O29: =IFERROR(MEDIAN(C29:L29),0) -> 0
B30: Fixed Asset Ratio | C30: =IFERROR(HistoricalFS!C5/HistoricalFS!C53,0) -> 4.6679375 | D30: =IFERROR(HistoricalFS!D5/HistoricalFS!D53,0) -> 5.0023294 | E30: =IFERROR(HistoricalFS!E5/HistoricalFS!E53,0) -> 4.8387858 | F30: =IFERROR(HistoricalFS!F5/HistoricalFS!F53,0) -> 5.4899007 | G30: =IFERROR(HistoricalFS!G5/HistoricalFS!G53,0) -> 5.2905022 | H30: =IFERROR(HistoricalFS!H5/HistoricalFS!H53,0) -> 5.0545298 | I30: =IFERROR(HistoricalFS!I5/HistoricalFS!I53,0) -> 6.0208202 | J30: =IFERROR(HistoricalFS!J5/HistoricalFS!J53,0) -> 7.3829312 | ... L30: =IFERROR(HistoricalFS!L5/HistoricalFS!L53,0) -> 7.7823484 | N30: =IFERROR(AVERAGE(C30:L30),0) -> 5.8536723 | O30: =IFERROR(MEDIAN(C30:L30),0) -> 5.3902015
B31: Capital Turnover Ratio | C31: =IFERROR(HistoricalFS!C5/SUM(HistoricalFS!C47:C48),0) -> 0.920005 | D31: =IFERROR(HistoricalFS!D5/SUM(HistoricalFS!D47:D48),0) -> 0.91450268 | E31: =IFERROR(HistoricalFS!E5/SUM(HistoricalFS!E47:E48),0) -> 0.97294509 | F31: =IFERROR(HistoricalFS!F5/SUM(HistoricalFS!F47:F48),0) -> 0.93998923 | G31: =IFERROR(HistoricalFS!G5/SUM(HistoricalFS!G47:G48),0) -> 0.99113008 | H31: =IFERROR(HistoricalFS!H5/SUM(HistoricalFS!H47:H48),0) -> 0.86511169 | I31: =IFERROR(HistoricalFS!I5/SUM(HistoricalFS!I47:I48),0) -> 0.90866592 | J31: =IFERROR(HistoricalFS!J5/SUM(HistoricalFS!J47:J48),0) -> 0.92367457 | ... L31: =IFERROR(HistoricalFS!L5/SUM(HistoricalFS!L47:L48),0) -> 0.84334909 | N31: =IFERROR(AVERAGE(C31:L31),0) -> 0.9146901 | O31: =IFERROR(MEDIAN(C31:L31),0) -> 0.91725384
B33: Debtor Days | C33: =IFERROR(365/C27,0) -> 0 | D33: =IFERROR(365/D27,0) -> 0 | E33: =IFERROR(365/E27,0) -> 0 | F33: =IFERROR(365/F27,0) -> 0 | G33: =IFERROR(365/G27,0) -> 0 | H33: =IFERROR(365/H27,0) -> 0 | I33: =IFERROR(365/I27,0) -> 0 | J33: =IFERROR(365/J27,0) -> 0 | ... L33: =IFERROR(365/L27,0) -> 0 | N33: =IFERROR(AVERAGE(C33:L33),0) -> 0 | O33: =IFERROR(MEDIAN(C33:L33),0) -> 0 | Q33: On an average Debtor pays u in days
B34: Payable Days | C34: =IFERROR(365/C28,0) -> 135.55426 | D34: =IFERROR(365/D28,0) -> 133.15885 | E34: =IFERROR(365/E28,0) -> 123.57824 | F34: =IFERROR(365/F28,0) -> 108.44746 | G34: =IFERROR(365/G28,0) -> 217.31707 | H34: =IFERROR(365/H28,0) -> 172.2871 | I34: =IFERROR(365/I28,0) -> 167.23756 | J34: =IFERROR(365/J28,0) -> 159.80499 | ... L34: =IFERROR(365/L28,0) -> 200.32868 | N34: =IFERROR(AVERAGE(C34:L34),0) -> 157.58298 | O34: =IFERROR(MEDIAN(C34:L34),0) -> 158.96029 | Q34: On an average YOU pays TO Creditor in days
B35: Inventory Days | C35: =IFERROR(365/C29,0) -> 0 | D35: =IFERROR(365/D29,0) -> 0 | E35: =IFERROR(365/E29,0) -> 0 | F35: =IFERROR(365/F29,0) -> 0 | G35: =IFERROR(365/G29,0) -> 0 | H35: =IFERROR(365/H29,0) -> 0 | I35: =IFERROR(365/I29,0) -> 0 | J35: =IFERROR(365/J29,0) -> 0 | ... L35: =IFERROR(365/L29,0) -> 0 | N35: =IFERROR(AVERAGE(C35:L35),0) -> 0 | O35: =IFERROR(MEDIAN(C35:L35),0) -> 0 | Q35: This is the sustainable Stock for days (Pre produced and stored)
B36: Cash Conversion Cycle | C36: =IFERROR(SUM(C33,C35)-C34,0) -> -135.55426 | D36: =IFERROR(SUM(D33,D35)-D34,0) -> -133.15885 | E36: =IFERROR(SUM(E33,E35)-E34,0) -> -123.57824 | F36: =IFERROR(SUM(F33,F35)-F34,0) -> -108.44746 | G36: =IFERROR(SUM(G33,G35)-G34,0) -> -217.31707 | H36: =IFERROR(SUM(H33,H35)-H34,0) -> -172.2871 | I36: =IFERROR(SUM(I33,I35)-I34,0) -> -167.23756 | J36: =IFERROR(SUM(J33,J35)-J34,0) -> -159.80499 | ... L36: =IFERROR(SUM(L33,L35)-L34,0) -> -200.32868 | N36: =IFERROR(AVERAGE(C36:L36),0) -> -157.58298 | O36: =IFERROR(MEDIAN(C36:L36),0) -> -158.96029 | Q36: Shows the Shortfall or longterm sustaining of Cash Conversion (Debtors+Inventory)-Pyables
B38: CFO/Sales | C38: =IFERROR(HistoricalFS!C78/HistoricalFS!C5,0) -> 2.3628955 | D38: =IFERROR(HistoricalFS!D78/HistoricalFS!D5,0) -> 1.764501 | E38: =IFERROR(HistoricalFS!E78/HistoricalFS!E5,0) -> 1.2437142 | F38: =IFERROR(HistoricalFS!F78/HistoricalFS!F5,0) -> 0.88275094 | G38: =IFERROR(HistoricalFS!G78/HistoricalFS!G5,0) -> 0.68101016 | H38: =IFERROR(HistoricalFS!H78/HistoricalFS!H5,0) -> 0.74572289 | I38: =IFERROR(HistoricalFS!I78/HistoricalFS!I5,0) -> 0.31748248 | J38: =IFERROR(HistoricalFS!J78/HistoricalFS!J5,0) -> 0.63590605 | ... L38: =IFERROR(HistoricalFS!L78/HistoricalFS!L5,0) -> 0.9347878 | N38: =IFERROR(AVERAGE(C38:L38),0) -> 1.0663478 | O38: =IFERROR(MEDIAN(C38:L38),0) -> 0.90876937
B39: CFO/Total Assets | C39: =IFERROR(HistoricalFS!C78/HistoricalFS!C64,0) -> 0.1734449 | D39: =IFERROR(HistoricalFS!D78/HistoricalFS!D64,0) -> 0.11937636 | E39: =IFERROR(HistoricalFS!E78/HistoricalFS!E64,0) -> 0.085085582 | F39: =IFERROR(HistoricalFS!F78/HistoricalFS!F64,0) -> 0.060914237 | G39: =IFERROR(HistoricalFS!G78/HistoricalFS!G64,0) -> 0.042576343 | H39: =IFERROR(HistoricalFS!H78/HistoricalFS!H64,0) -> 0.043020551 | I39: =IFERROR(HistoricalFS!I78/HistoricalFS!I64,0) -> 0.020021477 | J39: =IFERROR(HistoricalFS!J78/HistoricalFS!J64,0) -> 0.044473555 | ... L39: =IFERROR(HistoricalFS!L78/HistoricalFS!L64,0) -> 0.063639577 | N39: =IFERROR(AVERAGE(C39:L39),0) -> 0.072998931 | O39: =IFERROR(MEDIAN(C39:L39),0) -> 0.062276907
B40: CFO/ Total Debts | C40: =IFERROR(HistoricalFS!C78/HistoricalFS!C49,0) -> 0.19423737 | D40: =IFERROR(HistoricalFS!D78/HistoricalFS!D49,0) -> 0.13244337 | E40: =IFERROR(HistoricalFS!E78/HistoricalFS!E49,0) -> 0.093859296 | F40: =IFERROR(HistoricalFS!F78/HistoricalFS!F49,0) -> 0.067227797 | G40: =IFERROR(HistoricalFS!G78/HistoricalFS!G49,0) -> 0.047322942 | H40: =IFERROR(HistoricalFS!H78/HistoricalFS!H49,0) -> 0.047479618 | I40: =IFERROR(HistoricalFS!I78/HistoricalFS!I49,0) -> 0.022204062 | J40: =IFERROR(HistoricalFS!J78/HistoricalFS!J49,0) -> 0.049765436 | ... L40: =IFERROR(HistoricalFS!L78/HistoricalFS!L49,0) -> 0.072161057 | N40: =IFERROR(AVERAGE(C40:L40),0) -> 0.081392236 | O40: =IFERROR(MEDIAN(C40:L40),0) -> 0.069694427

Sheet Foreacasting
B4: ='Data Sheet'!B1&" - "&'Data Sheet'!A17&" Forecast" -> INDIAN BANK - Sales Forecast | G4: ='Data Sheet'!B1&" - "&HistoricalFS!B17&" Forecast " -> INDIAN BANK - EBITDA Forecast | L4: ='Data Sheet'!B1&" - "&HistoricalFS!B26&" Forecast " -> INDIAN BANK - Earning Before Tax Forecast
B5: Year Weight | C5: Year | D5: Sales | E5: Sales Growth | G5: Year Weight | H5: Year | I5: Sales | J5: Sales Growth | L5: Year Weight | M5: Year | N5: Sales | O5: Sales Growth
B6: 1 | C6: ='Data Sheet'!$B$16 -> 42825 | D6: {=TRANSPOSE('Data Sheet'!B17:K17)} -> 16039.22 | G6: 1 | H6: 42460 | I6: {=TRANSPOSE(HistoricalFS!C17:M17)} -> 9895.65 | L6: 1 | M6: 42460 | N6: {=TRANSPOSE(HistoricalFS!C26:M26)} -> -1162.05
B7: 2 | C7: =C6+365 -> 43190 | D7: 17115.32 | E7: =D7/D6-1 -> 0.067091791 | G7: 2 | H7: 42825 | I7: 10117.02 | J7: =I7/I6-1 -> 0.022370435 | L7: 2 | M7: 42825 | N7: -971.1 | O7: =N7/N6-1 -> -0.16432167
B8: 3 | C8: =C7+365 -> 43555 | D8: 19182.06 | E8: =D8/D7-1 -> 0.1207538 | G8: 3 | H8: 43190 | I8: 10893.27 | J8: =I8/I7-1 -> 0.076727139 | L8: 3 | M8: 43190 | N8: -1532.77 | O8: =N8/N7-1 -> 0.57838534
B9: 4 | C9: =C8+365 -> 43920 | D9: 21401.28 | E9: =D9/D8-1 -> 0.11569248 | G9: 4 | H9: 43555 | I9: 12163.47 | J9: =I9/I8-1 -> 0.11660411 | L9: 4 | M9: 43555 | N9: -1948.05 | O9: =N9/N8-1 -> 0.27093432
B10: 5 | C10: =C9+365 -> 44285 | D10: 39108.08 | E10: =D10/D9-1 -> 0.82737107 | G10: 5 | H10: 43920 | I10: 21079.12 | J10: =I10/I9-1 -> 0.73298574 | L10: 5 | M10: 43920 | N10: -2996.58 | O10: =N10/N9-1 -> 0.53824594
B11: 6 | C11: =C10+365 -> 44650 | D11: 38888.44 | E11: =D11/D10-1 -> -0.0056162307 | G11: 6 | H11: 44285 | I11: 18603.7 | J11: =I11/I10-1 -> -0.11743469 | L11: 6 | M11: 44285 | N11: -4126.41 | O11: =N11/N10-1 -> 0.37703983
B12: 7 | C12: =C11+365 -> 45015 | D12: 44985.16 | E12: =D12/D11-1 -> 0.15677461 | G12: 7 | H12: 44650 | I12: 23408.37 | J12: =I12/I11-1 -> 0.25826422 | L12: 7 | M12: 44650 | N12: -1841.31 | O12: =N12/N11-1 -> -0.55377435
B13: 8 | C13: =C12+365 -> 45380 | D13: 55649.73 | E13: =D13/D12-1 -> 0.23706862 | G13: 8 | H13: 45015 | I13: 35307.3 | J13: =I13/I12-1 -> 0.50831946 | L13: 8 | M13: 45015 | N13: 2435.4 | O13: =N13/N12-1 -> -2.3226453
B14: 9 | C14: =C13+365 -> 45745 | D14: 62039.43 | E14: =D14/D13-1 -> 0.11481996 | G14: 9 | H14: 45380 | I14: 42221.25 | J14: =I14/I13-1 -> 0.19582211 | L14: 9 | M14: 45380 | N14: 4852.06 | O14: =N14/N13-1 -> 0.99230517
B15: 10 | C15: =C14+365 -> 46110 | D15: 67504.09 | E15: =D15/D14-1 -> 0.088083659 | G15: 10 | H15: 45745 | I15: 46793.97 | J15: =I15/I14-1 -> 0.10830376 | L15: 10 | M15: 45745 | N15: 5646.45 | O15: =N15/N14-1 -> 0.16372221
B16: 11 | C16: =C15+365 -> 46475 | D16: =FORECAST(B16,$D$6:$D$15,$B$6:$B$15) -> 72542.046 | E16: =D16/D15-1 -> 0.074631863 | G16: 11 | H16: 46110 | I16: =FORECAST(G16,$I$6:$I$15,$G$6:$G$15) -> 46719.776 | J16: =I16/I15-1 -> -0.0015855462 | L16: 11 | M16: 46110 | N16: =FORECAST(L16,$N$6:$N$15,$L$6:$L$15) -> 3871.226 | O16: =N16/N15-1 -> -0.31439648
B17: 12 | C17: =C16+365 -> 46840 | D17: =FORECAST(B17,$D$6:$D$15,$B$6:$B$15) -> 78787.64 | E17: =D17/D16-1 -> 0.086096188 | G17: 12 | H17: 46475 | I17: =FORECAST(G17,$I$6:$I$15,$G$6:$G$15) -> 51023.679 | J17: =I17/I16-1 -> 0.092121643 | L17: 12 | M17: 46475 | N17: =FORECAST(L17,$N$6:$N$15,$L$6:$L$15) -> 4604.9827 | O17: =N17/N16-1 -> 0.18954118
B18: 13 | C18: =C17+365 -> 47205 | D18: =FORECAST(B18,$D$6:$D$15,$B$6:$B$15) -> 85033.233 | E18: =D18/D17-1 -> 0.079271237 | G18: 13 | H18: 46840 | I18: =FORECAST(G18,$I$6:$I$15,$G$6:$G$15) -> 55327.581 | J18: =I18/I17-1 -> 0.084351083 | L18: 13 | M18: 46840 | N18: =FORECAST(L18,$N$6:$N$15,$L$6:$L$15) -> 5338.7395 | O18: =N18/N17-1 -> 0.15933973
B19: 14 | C19: =C18+365 -> 47570 | D19: =FORECAST(B19,$D$6:$D$15,$B$6:$B$15) -> 91278.827 | E19: =D19/D18-1 -> 0.073448855 | G19: 14 | H19: 47205 | I19: =FORECAST(G19,$I$6:$I$15,$G$6:$G$15) -> 59631.484 | J19: =I19/I18-1 -> 0.077789458 | L19: 14 | M19: 47205 | N19: =FORECAST(L19,$N$6:$N$15,$L$6:$L$15) -> 6072.4962 | O19: =N19/N18-1 -> 0.13744007
B20: 15 | C20: =C19+365 -> 47935 | D20: =FORECAST(B20,$D$6:$D$15,$B$6:$B$15) -> 97524.421 | E20: =D20/D19-1 -> 0.068423246 | G20: 15 | H20: 47570 | I20: =FORECAST(G20,$I$6:$I$15,$G$6:$G$15) -> 63935.386 | J20: =I20/I19-1 -> 0.072175004 | L20: 15 | M20: 47570 | N20: =FORECAST(L20,$N$6:$N$15,$L$6:$L$15) -> 6806.2529 | O20: =N20/N19-1 -> 0.1208328
B21: 16 | C21: =C20+365 -> 48300 | D21: =FORECAST(B21,$D$6:$D$15,$B$6:$B$15) -> 103770.01 | E21: =D21/D20-1 -> 0.06404133 | G21: 16 | H21: 47935 | I21: =FORECAST(G21,$I$6:$I$15,$G$6:$G$15) -> 68239.289 | J21: =I21/I20-1 -> 0.067316439 | L21: 16 | M21: 47935 | N21: =FORECAST(L21,$N$6:$N$15,$L$6:$L$15) -> 7540.0096 | O21: =N21/N20-1 -> 0.10780627
B22: 17 | C22: =C21+365 -> 48665 | D22: =FORECAST(B22,$D$6:$D$15,$B$6:$B$15) -> 110015.61 | E22: =D22/D21-1 -> 0.060186882 | G22: 17 | H22: 48300 | I22: =FORECAST(G22,$I$6:$I$15,$G$6:$G$15) -> 72543.191 | J22: =I22/I21-1 -> 0.063070742 | L22: 17 | M22: 48300 | N22: =FORECAST(L22,$N$6:$N$15,$L$6:$L$15) -> 8273.7664 | O22: =N22/N21-1 -> 0.097315091

Sheet Data>

Sheet Data Sheet
A1: COMPANY NAME | B1: INDIAN BANK | E1: =IF(B2<>B3, "A NEW VERSION OF THE WORKSHEET IS AVAILABLE", "")
A2: LATEST VERSION | B2: 2.1 | E2: PLEASE DO NOT MAKE ANY CHANGES TO THIS SHEET
A3: CURRENT VERSION | B3: 2.1
B4: ='Data Sheet'!B1&" -" -> INDIAN BANK -
A5: META
A6: Number of shares | B6: =IF(B9>0, B9/B8, 0) -> 134.69635
A7: Face Value | B7: 10
A8: Current Price | B8: 857.05 | C8: =IFERROR('Data Sheet'!C18,'Data Sheet'!C20:C22)*-1 -> 0
A9: Market Capitalization | B9: 115441.51
A15: PROFIT & LOSS
A16: Report Date | B16: 42825 | C16: 43190 | D16: 43555 | E16: 43921 | F16: 44286 | G16: 44651 | H16: 45016 | I16: 45382 | J16: 45747 | K16: 46112
A17: Sales | B17: 16039.22 | C17: 17115.32 | D17: 19182.06 | E17: 21401.28 | F17: 39108.08 | G17: 38888.44 | H17: 44985.16 | I17: 55649.73 | J17: 62039.43 | K17: 67504.09
A18: Raw Material Cost
A19: Change in Inventory
A20: Power and Fuel
A21: Other Mfr. Exp | B21: 93.6 | C21: 94.57 | D21: 95.21 | E21: 93.96 | F21: 201.76 | G21: 246.33 | H21: 195.34 | I21: 252.83 | J21: 274.02 | K21: 280.32
A22: Employee Cost | B22: 1996.2 | C22: 2105.54 | D22: 2228.71 | E22: 2479.28 | F22: 6412.39 | G22: 6739.61 | H22: 7580.41 | I22: 9322.06 | J22: 9977.08 | K22: 10883.62
A23: Selling and admin | B23: 607.15 | C23: 640.96 | D23: 706.05 | E23: 739.22 | F23: 1573.52 | G23: 1652.98 | H23: 1807.53 | I23: 1816.52 | J23: 1975.06 | K23: 2253.58
A24: Other Expenses | B24: 3446.62 | C24: 4157.23 | D24: 5258.82 | E24: 5925.35 | F24: 9841.29 | G24: 11645.82 | H24: 11993.51 | I24: 8951.02 | J24: 7592.02 | K24: 7292.6
A25: Other Income | B25: 2222.4 | C25: 2416.59 | D25: 1891.44 | E25: 3325.5 | F25: 6111.4 | G25: 7379.71 | H25: 7804.5 | I25: 8581.95 | J25: 10011.45 | K25: 10828.61
A26: Depreciation | B26: 166.24 | C26: 236.84 | D26: 259.29 | E26: 314.01 | F26: 636.9 | G26: 600.86 | H26: 532.39 | I26: 531.14 | J26: 542.94 | K26: 608.86
A27: Interest | B27: 10891.46 | C27: 10851.28 | D27: 12166.75 | E27: 13797.51 | F27: 23438.8 | G27: 22129.25 | H27: 24717.29 | I27: 32340.76 | J27: 36826.25 | K27: 40538.66
A28: Profit before tax | B28: 1060.35 | C28: 1445.49 | D28: 358.67 | E28: 1377.45 | F28: 3114.82 | G28: 3253.3 | H28: 5963.19 | I28: 11017.35 | J28: 14863.51 | K28: 16475.06
A29: Tax | B29: -352.56 | C29: 182.57 | D29: 37.74 | E29: 619.37 | F29: 99.1 | G29: -740.59 | H29: 632.71 | I29: 2888.2 | J29: 3868.64 | K29: 4248.07
A30: Net profit | B30: 1453.06 | C30: 1310.54 | D30: 380.13 | E30: 861.34 | F30: 3149.15 | G30: 4141.81 | H30: 5572.31 | I30: 8419.41 | J30: 11261.47 | K30: 11704.28
A31: Dividend Amount | B31: 288.17 | F31: 225.87 | G31: 809.54 | H31: 1071.08 | I31: 1616.35 | J31: 2188.81 | K31: 2458.2
A40: Quarters
A41: Report Date | B41: 45382 | C41: 45473 | D41: 45565 | E41: 45657 | F41: 45747 | G41: 45838 | H41: 45930 | I41: 46022 | J41: 46112 | K41: 46203
A42: Sales | B42: 14633.41 | C42: 15040.63 | D42: 15369.01 | E42: 15770.16 | F42: 15859.63 | G42: 16285.1 | H42: 16628.28 | I42: 17102.21 | J42: 17488.5 | K42: 18095.14
A43: Expenses | B43: 5378.16 | C43: 4994.32 | D43: 5143.73 | E43: 5101.71 | F43: 5097.49 | G43: 4880.15 | H43: 5108.39 | I43: 5492.5 | J43: 5811.46 | K43: 5946.06
A44: Other Income | B44: 2432.08 | C44: 2077.13 | D44: 2602.21 | E44: 2397.38 | F44: 2934.73 | G44: 1853.91 | H44: 2642.81 | I44: 2792.57 | J44: 2772.73 | K44: 2902.24
A45: Depreciation
A46: Interest | B46: 8609.13 | C46: 8860.51 | D46: 9153.5 | E46: 9345.18 | F46: 9467.06 | G46: 9924.09 | H46: 10039.71 | I46: 10202.9 | J46: 10371.96 | K46: 10656.86
A47: Profit before tax | B47: 3078.2 | C47: 3262.93 | D47: 3673.99 | E47: 3720.65 | F47: 4229.81 | G47: 3334.77 | H47: 4122.99 | I47: 4199.38 | J47: 4077.81 | K47: 4394.46
A48: Tax | B48: 817.89 | C48: 845.63 | D48: 933.96 | E48: 844.5 | F48: 1268.42 | G48: 1116.26 | H48: 1082.46 | I48: 1113.22 | J48: 962.61 | K48: 1094.98
A49: Net profit | B49: 2295.61 | C49: 2570.4 | D49: 2799.7 | E49: 2909.73 | F49: 2981.64 | G49: 2276.37 | H49: 3107.97 | I49: 3146.88 | J49: 3173.05 | K49: 3356.63
A50: Operating Profit | B50: 9255.25 | C50: 10046.31 | D50: 10225.28 | E50: 10668.45 | F50: 10762.14 | G50: 11404.95 | H50: 11519.89 | I50: 11609.71 | J50: 11677.04 | K50: 12149.08
A51: EBITDA | B51: 16892.02 | C51: 20164.6 | D51: 19850 | E51: 20404 | F51: 22268 | G51: 23828 | H51: 22359 | I51: 18164 | J51: 17822 | K51: 22113
A55: BALANCE SHEET
A56: Report Date | B56: 42825 | C56: 43190 | D56: 43555 | E56: 43921 | F56: 44286 | G56: 44651 | H56: 45016 | I56: 45382 | J56: 45747 | K56: 46112
...

Sheet Cash Flow statement
C2: 42430 | D2: 42795 | E2: 43160 | F2: 43525 | G2: 43891 | H2: 44256 | I2: 44621 | J2: 44986 | K2: 45352 | L2: 45717
B3: Cash from Operating Activity - | C3: 37900 | D3: 30199 | E3: 23857 | F3: 18891 | G3: 26633 | H3: 29001 | I3: 14283 | J3: 35388 | K3: 67915 | L3: 63102
B4: Profit from operations | C4: 38626 | D4: 28840 | E4: 33312 | F4: 28771 | G4: 23352 | H4: 31198 | I4: 26943 | J4: 41694 | K4: 65106 | L4: 58937
B5: Receivables | C5: -2223 | D5: -4152 | E5: -10688 | F5: -9109 | G5: 9950 | H5: -5505 | I5: 185 | J5: -2213 | K5: -1876 | L5: 3573
B6: Inventory | C6: -5743 | D6: -6621 | E6: -3560 | F6: 2069 | G6: 2326 | H6: 3814 | I6: 472 | J6: -5665 | K6: -7265 | L6: 2127
B7: Payables | C7: 3947 | D7: 9301 | E7: 7320 | F7: -4692 | G7: -8085 | H7: 5748 | I7: -7012 | J7: 6945 | K7: 13706 | L7: 1303
B8: Loans Advances | C8: -520 | D8: 0 | E8: 0 | F8: 0 | G8: 0 | H8: 0 | I8: 0 | J8: 0 | K8: 0 | L8: 0
B9: Other WC items | C9: 5852 | D9: 4727 | E9: 494 | F9: 4512 | G9: 875 | H9: -4150 | I9: -4396 | J9: -2194 | K9: 2760 | L9: 1153
B10: Direct taxes | C10: -2040 | D10: -1895 | E10: -3021 | F10: -2659 | G10: -1785 | H10: -2105 | I10: -1910 | J10: -3179 | K10: -4516 | L10: -3991
B11: Cash from Investing Activity - | C11: -36694 | D11: -39571 | E11: -25139 | F11: -20878 | G11: -33115 | H11: -25672 | I11: -4444 | J11: -15417 | K11: -22781 | L11: -49982
B12: Fixed assets purchased | C12: -31503 | D12: -16072 | E12: -35079 | F12: -35304 | G12: -29702 | H12: -20205 | I12: -15168 | J12: -19230 | K12: -31414 | L12: -38042
B13: Fixed assets sold | C13: 59 | D13: 53 | E13: 30 | F13: 67 | G13: 171 | H13: 351 | I13: 230 | J13: 285 | K13: 231 | L13: 974
B14: Investments purchased | C14: -4728 | D14: -6 | E14: -329 | F14: -130 | G14: -1439 | H14: -7530 | I14: -3008 | J14: -50 | K14: -74 | L14: -12677
... B32: Net Cash Flow | C32: -2589 | D32: -3167 | E32: 730 | F32: 6843 | G32: -3092 | H32: 13232 | I32: 6459 | J32: -6272 | K32: 8128 | L32: -5666
