Workbook
Name Beta: '[1]Simplification>'!$C$5
Name Cost_Of_debt: '[1]Simplify using Name'!$C$9
Name Cost_Of_equity: '[1]Simplify using Name'!$C$7
Name CostofDebt: '[1]Simplification>'!$C$6
Name Current_Sales: '[1]Simplify using Name'!$G$8
Name Debt_Funding: '[1]Simplify using Name'!$C$16
Name Debt_Value: '[1]Simplify using Name'!$C$14
Name DebtValue: '[1]Simplification>'!$C$9
Name Equity_Funding: '[1]Simplify using Name'!$C$15
Name Equity_Value: '[1]Simplify using Name'!$C$13
Name EquityValue: '[1]Simplification>'!$C$8
Name Gross_Margin: '[1]Simplify using Name'!$G$10
Name MarketReturn: '[1]Simplification>'!$C$4
Name Post_Tax_Cost_of_Debt: '[1]Simplify using Name'!$C$11
Name Riskfreerate: '[1]Simplification>'!$C$3
Name Sales_Growth: '[1]Simplify using Name'!$G$9
Name Taper_rate: 'DCF Model'!$C$21
Name Tax_rate: 'DCF Model'!$C$27
Name TAXRate: '[1]Simplification>'!$C$7
Name UPDATE: 'Data Sheet'!$E$1
Name UPDATE: '[2]Data Sheet'!$E$1

Sheet DCF Model
B2: Discounted Cashflow Model
B3: Financial Modelling Course
B6: Company Overview
B7: Indian Bank is a premier public sector financial institution in India headquartered in Chennai, Tamil Nadu
B9: Founded: March 5, 1907 (commenced business on August 15, 1907)
B10: Headquarters: Chennai, India
B11: Ownership: Majority owned by the Government of India.
B12: Leadership: Led by Managing Director and CEO Shri Binod Kumar.
B13: Operates over 6,000 domestic branches alongside international branches and an IBU in Gift City.
B16: Key Assumption And Methodology
B17: Parameter | C17: Value | D17: Rationale
B18: Valuation Date
B19: Projection Period
C20: 0.2 | D20: Based On management guidance
B21: Annual Growth Tapering | C21: 0.02
B23: Terminal Growth Rate | C23: 0.06 | D23: Conservative long term growth considering India's GDP and retail sector potential
B25: Risk Free Rate (RF) | C25: 0.065 | D25: India 10 year bond yield
B26: EquityRisk Premium (ERP) | C26: =12%-C25 -> 0.055 | D26: Exprcted return over RFR for equity investors
B27: Tax Rate | C27: 0.25 | D27: Effective Tax Rate based of historical performance
B30: Income Statement
B31: Particulars | C31: 43190 | D31: 43555 | E31: 43921 | F31: 44286 | G31: 44651 | H31: 45016 | I31: 45382 | J31: 45747 | K31: 46112 | L31: 46112
B32: Sales | C32: ='Data Sheet'!B17 -> 16039.22 | D32: ='Data Sheet'!C17 -> 17115.32 | E32: ='Data Sheet'!D17 -> 19182.06 | F32: ='Data Sheet'!E17 -> 21401.28 | G32: ='Data Sheet'!F17 -> 39108.08 | H32: ='Data Sheet'!G17 -> 38888.44 | I32: ='Data Sheet'!H17 -> 44985.16 | J32: ='Data Sheet'!I17 -> 55649.73 | ... L32: ='Data Sheet'!K17 -> 67504.09
B33: % Of growth | D33: =D32/C32-1 -> 0.067091791 | E33: =E32/D32-1 -> 0.1207538 | F33: =F32/E32-1 -> 0.11569248 | G33: =G32/F32-1 -> 0.82737107 | H33: =H32/G32-1 -> -0.0056162307 | I33: =I32/H32-1 -> 0.15677461 | J33: =J32/I32-1 -> 0.23706862 | K33: =K32/J32-1 -> 0.11481996 | L33: =L32/K32-1 -> 0.088083659
B34: COGS | C34: ='Data Sheet'!B21 -> 93.6 | D34: ='Data Sheet'!C21 -> 94.57 | E34: ='Data Sheet'!D21 -> 95.21 | F34: ='Data Sheet'!E21 -> 93.96 | G34: ='Data Sheet'!F21 -> 201.76 | H34: ='Data Sheet'!G21 -> 246.33 | I34: ='Data Sheet'!H21 -> 195.34 | J34: ='Data Sheet'!I21 -> 252.83 | ... L34: ='Data Sheet'!K21 -> 280.32
B35: % of revenue | C35: =C34/C32 -> 0.0058356953 | D35: =D34/D32 -> 0.0055254591 | E35: =E34/E32 -> 0.0049634919 | F35: =F34/F32 -> 0.0043903916 | G35: =G34/G32 -> 0.0051590362 | H35: =H34/H32 -> 0.0063342731 | I35: =I34/I32 -> 0.0043423209 | J35: =J34/J32 -> 0.0045432386 | ... L35: =L34/L32 -> 0.0041526373
B36: Gross Profit | C36: =C32-C34 -> 15945.62 | D36: =D32-D34 -> 17020.75 | E36: =E32-E34 -> 19086.85 | F36: =F32-F34 -> 21307.32 | G36: =G32-G34 -> 38906.32 | H36: =H32-H34 -> 38642.11 | I36: =I32-I34 -> 44789.82 | J36: =J32-J34 -> 55396.9 | ... L36: =L32-L34 -> 67223.77
B37: % Margin | C37: =C36/C32 -> 0.9941643 | D37: =D36/D32 -> 0.99447454 | E37: =E36/E32 -> 0.99503651 | F37: =F36/F32 -> 0.99560961 | G37: =G36/G32 -> 0.99484096 | H37: =H36/H32 -> 0.99366573 | I37: =I36/I32 -> 0.99565768 | J37: =J36/J32 -> 0.99545676 | ... L37: =L36/L32 -> 0.99584736
B38: Operating Expenses | C38: =SUM('Data Sheet'!B22:B24) -> 6049.97 | D38: =SUM('Data Sheet'!C22:C24) -> 6903.73 | E38: =SUM('Data Sheet'!D22:D24) -> 8193.58 | F38: =SUM('Data Sheet'!E22:E24) -> 9143.85 | G38: =SUM('Data Sheet'!F22:F24) -> 17827.2 | H38: =SUM('Data Sheet'!G22:G24) -> 20038.41 | I38: =SUM('Data Sheet'!H22:H24) -> 21381.45 | J38: =SUM('Data Sheet'!I22:I24) -> 20089.6 | ... L38: =SUM('Data Sheet'!K22:K24) -> 20429.8
B39: % Revenue | C39: =C38/C32 -> 0.37719852 | D39: =D38/D32 -> 0.40336552 | E39: =E38/E32 -> 0.42714807 | F39: =F38/F32 -> 0.42725715 | G39: =G38/G32 -> 0.45584442 | H39: =H38/H32 -> 0.51527935 | I39: =I38/I32 -> 0.47530008 | J39: =J38/J32 -> 0.36100085 | ... L39: =L38/L32 -> 0.30264537
B40: EBITDA | C40: =C36-C38 -> 9895.65 | D40: =D36-D38 -> 10117.02 | E40: =E36-E38 -> 10893.27 | F40: =F36-F38 -> 12163.47 | G40: =G36-G38 -> 21079.12 | H40: =H36-H38 -> 18603.7 | I40: =I36-I38 -> 23408.37 | J40: =J36-J38 -> 35307.3 | ... L40: =L36-L38 -> 46793.97
B41: % Revenue | C41: =C40/C32 -> 0.61696579 | D41: =D40/D32 -> 0.59110902 | E41: =E40/E32 -> 0.56788843 | F41: =F40/F32 -> 0.56835245 | G41: =G40/G32 -> 0.53899654 | H41: =H40/H32 -> 0.47838638 | I41: =I40/I32 -> 0.5203576 | J41: =J40/J32 -> 0.63445591 | ... L41: =L40/L32 -> 0.693202
B42: Depreciation | C42: ='Data Sheet'!B26 -> 166.24 | D42: ='Data Sheet'!C26 -> 236.84 | E42: ='Data Sheet'!D26 -> 259.29 | F42: ='Data Sheet'!E26 -> 314.01 | G42: ='Data Sheet'!F26 -> 636.9 | H42: ='Data Sheet'!G26 -> 600.86 | I42: ='Data Sheet'!H26 -> 532.39 | J42: ='Data Sheet'!I26 -> 531.14 | ... L42: ='Data Sheet'!K26 -> 608.86
B43: % Of Sales | C43: =C42/C32 -> 0.010364594 | D43: =D42/D32 -> 0.013837895 | E43: =E42/E32 -> 0.013517318 | F43: =F42/F32 -> 0.014672487 | G43: =G42/G32 -> 0.016285637 | H43: =H42/H32 -> 0.015450864 | I43: =I42/I32 -> 0.011834792 | J43: =J42/J32 -> 0.009544341 | ... L43: =L42/L32 -> 0.0090196016
B44: EBIT | C44: =C40-C42 -> 9729.41 | D44: =D40-D42 -> 9880.18 | E44: =E40-E42 -> 10633.98 | F44: =F40-F42 -> 11849.46 | G44: =G40-G42 -> 20442.22 | H44: =H40-H42 -> 18002.84 | I44: =I40-I42 -> 22875.98 | J44: =J40-J42 -> 34776.16 | ... L44: =L40-L42 -> 46185.11
B45: % Margin | C45: =C44/C32 -> 0.60660119 | D45: =D44/D32 -> 0.57727112 | E45: =E44/E32 -> 0.55437112 | F45: =F44/F32 -> 0.55367997 | G45: =G44/G32 -> 0.52271091 | H45: =H44/H32 -> 0.46293552 | I45: =I44/I32 -> 0.50852281 | J45: =J44/J32 -> 0.62491157 | ... L45: =L44/L32 -> 0.6841824
B46: Other Income | C46: ='Data Sheet'!B25 -> 2222.4 | D46: ='Data Sheet'!C25 -> 2416.59 | E46: ='Data Sheet'!D25 -> 1891.44 | F46: ='Data Sheet'!E25 -> 3325.5 | G46: ='Data Sheet'!F25 -> 6111.4 | H46: ='Data Sheet'!G25 -> 7379.71 | I46: ='Data Sheet'!H25 -> 7804.5 | J46: ='Data Sheet'!I25 -> 8581.95 | ... L46: ='Data Sheet'!K25 -> 10828.61
B47: Interest | C47: ='Data Sheet'!B27 -> 10891.46 | D47: ='Data Sheet'!C27 -> 10851.28 | E47: ='Data Sheet'!D27 -> 12166.75 | F47: ='Data Sheet'!E27 -> 13797.51 | G47: ='Data Sheet'!F27 -> 23438.8 | H47: ='Data Sheet'!G27 -> 22129.25 | I47: ='Data Sheet'!H27 -> 24717.29 | J47: ='Data Sheet'!I27 -> 32340.76 | ... L47: ='Data Sheet'!K27 -> 40538.66
B48: % Debt | C48: =C47/'Data Sheet'!B59 -> 0.055820169 | D48: =D47/'Data Sheet'!C59 -> 0.047588746 | E48: =E47/'Data Sheet'!D59 -> 0.047866982 | F48: =F47/'Data Sheet'!E59 -> 0.049098889 | G48: =G47/'Data Sheet'!F59 -> 0.041647316 | H48: =H47/'Data Sheet'!G59 -> 0.036230632 | I48: =I47/'Data Sheet'!H59 -> 0.038427688 | J48: =J47/'Data Sheet'!I59 -> 0.045480163 | ... L48: =L47/'Data Sheet'!K59 -> 0.046358476
B49: PBT | C49: =C44+C46-C47 -> 1060.35 | D49: =D44+D46-D47 -> 1445.49 | E49: =E44+E46-E47 -> 358.67 | F49: =F44+F46-F47 -> 1377.45 | G49: =G44+G46-G47 -> 3114.82 | H49: =H44+H46-H47 -> 3253.3 | I49: =I44+I46-I47 -> 5963.19 | J49: =J44+J46-J47 -> 11017.35 | ... L49: =L44+L46-L47 -> 16475.06
B50: % Revenue | C50: =C49/C32 -> 0.066109823 | D50: =D49/D32 -> 0.084455914 | E50: =E49/E32 -> 0.0186982 | F50: =F49/F32 -> 0.064362973 | G50: =G49/G32 -> 0.079646457 | H50: =H49/H32 -> 0.083657251 | I50: =I49/I32 -> 0.13255905 | J50: =J49/J32 -> 0.1979767 | ... L50: =L49/L32 -> 0.24406017
...

Sheet Comps
B3: Comps Data
B4: Name | C4: Mar Cap ₹ Cr | D4: Debt ₹ Cr | E4: Debt / Eq | F4: Sales ₹ Cr | G4: Beta | H4: Cash & Equivalents ₹ Cr
B5: SBI | C5: 930400 | D5: 777302 | E5: 11.08 | F5: 136240.49 | G5: 1.05 | H5: 212013.35
B6: Union Bank | C6: 139893 | D6: 77798 | E6: 9.74 | F6: 27427.1 | G6: 1.42 | H6: 43255.93
B7: Punjab National Bank | C7: 133145 | D7: 107558 | E7: 11.79 | F7: 33589.17 | G7: 1.24 | H7: 71273.23
B8: Bank of Baroda | C8: 122587 | D8: 156357.45 | E8: 10.89 | F8: 35114.52 | G8: 1.26 | H8: 50665.14
B9: Indian Bank | C9: 115792 | D9: 46807 | E9: 10.64 | F9: 18095.14 | G9: 1.33 | H9: 31796
B11: Industry Beta
B13: Name | C13: Equit Value | D13: Total Debt | E13: Debt/Equity | F13: Debt /Capital | G13: Tax Rate % | H13: Levered Beta | I13: Unlivered Beta
B14: SBI | C14: =C5 -> 930400 | D14: =D5 -> 777302 | E14: =D14/C14 -> 0.83544927 | F14: =D14/(C14+D14) -> 0.45517426 | G14: =Tax_rate -> 0.25 | H14: =G5 -> 1.05 | I14: =H14/(1+E14)*(1-G14) -> 0.42905027
B15: Union Bank | C15: =C6 -> 139893 | D15: =D6 -> 77798 | E15: =D15/C15 -> 0.55612504 | F15: =D15/(C15+D15) -> 0.35737812 | G15: =Tax_rate -> 0.25 | H15: =G6 -> 1.42 | I15: =H15/(1+E15)*(1-G15) -> 0.6843923
B16: Punjab National Bank | C16: =C7 -> 133145 | D16: =D7 -> 107558 | E16: =D16/C16 -> 0.80782605 | F16: =D16/(C16+D16) -> 0.44684944 | G16: =Tax_rate -> 0.25 | H16: =G7 -> 1.24 | I16: =H16/(1+E16)*(1-G16) -> 0.51443002
B17: Bank of Baroda | C17: =C8 -> 122587 | D17: =D8 -> 156357.45 | E17: =D17/C17 -> 1.2754815 | F17: =D17/(C17+D17) -> 0.56053257 | G17: =Tax_rate -> 0.25 | H17: =G8 -> 1.26 | I17: =H17/(1+E17)*(1-G17) -> 0.41529672
B18: Average | E18: =AVERAGE(E14:E17) -> 0.86872046 | F18: =AVERAGE(F14:F17) -> 0.4549836 | G18: =AVERAGE(G14:G17) -> 0.25 | H18: =AVERAGE(H14:H17) -> 1.2425 | I18: =AVERAGE(I14:I17) -> 0.51079233
B19: Median | E19: =MEDIAN(E14:E17) -> 0.82163766 | F19: =MEDIAN(F14:F17) -> 0.45101185 | G19: =MEDIAN(G14:G17) -> 0.25 | H19: =MEDIAN(H14:H17) -> 1.25 | I19: =MEDIAN(I14:I17) -> 0.47174015

Sheet Data Sheet
A1: COMPANY NAME | B1: INDIAN BANK | E1: =IF(B2<>B3, "A NEW VERSION OF THE WORKSHEET IS AVAILABLE", "")
A2: LATEST VERSION | B2: 2.1 | E2: PLEASE DO NOT MAKE ANY CHANGES TO THIS SHEET
A3: CURRENT VERSION | B3: 2.1
B4: ='Data Sheet'!B1&" -" -> INDIAN BANK -
A5: META
A6: Number of shares | B6: =IF(B9>0, B9/B8, 0) -> 134.69635
A7: Face Value | B7: 10
A8: Current Price | B8: 857.05 | C8: =IFERROR('Data Sheet'!C18,'Data Sheet'!C20:C22)*-1 -> 0
A9: Market Capitalization | B9: 115441.51
A15: PROFIT & LOSS
A16: Report Date | B16: 42825 | C16: 43190 | D16: 43555 | E16: 43921 | F16: 44286 | G16: 44651 | H16: 45016 | I16: 45382 | J16: 45747 | K16: 46112
A17: Sales | B17: 16039.22 | C17: 17115.32 | D17: 19182.06 | E17: 21401.28 | F17: 39108.08 | G17: 38888.44 | H17: 44985.16 | I17: 55649.73 | J17: 62039.43 | K17: 67504.09
A18: Raw Material Cost
A19: Change in Inventory
A20: Power and Fuel
A21: Other Mfr. Exp | B21: 93.6 | C21: 94.57 | D21: 95.21 | E21: 93.96 | F21: 201.76 | G21: 246.33 | H21: 195.34 | I21: 252.83 | J21: 274.02 | K21: 280.32
A22: Employee Cost | B22: 1996.2 | C22: 2105.54 | D22: 2228.71 | E22: 2479.28 | F22: 6412.39 | G22: 6739.61 | H22: 7580.41 | I22: 9322.06 | J22: 9977.08 | K22: 10883.62
A23: Selling and admin | B23: 607.15 | C23: 640.96 | D23: 706.05 | E23: 739.22 | F23: 1573.52 | G23: 1652.98 | H23: 1807.53 | I23: 1816.52 | J23: 1975.06 | K23: 2253.58
A24: Other Expenses | B24: 3446.62 | C24: 4157.23 | D24: 5258.82 | E24: 5925.35 | F24: 9841.29 | G24: 11645.82 | H24: 11993.51 | I24: 8951.02 | J24: 7592.02 | K24: 7292.6
A25: Other Income | B25: 2222.4 | C25: 2416.59 | D25: 1891.44 | E25: 3325.5 | F25: 6111.4 | G25: 7379.71 | H25: 7804.5 | I25: 8581.95 | J25: 10011.45 | K25: 10828.61
A26: Depreciation | B26: 166.24 | C26: 236.84 | D26: 259.29 | E26: 314.01 | F26: 636.9 | G26: 600.86 | H26: 532.39 | I26: 531.14 | J26: 542.94 | K26: 608.86
A27: Interest | B27: 10891.46 | C27: 10851.28 | D27: 12166.75 | E27: 13797.51 | F27: 23438.8 | G27: 22129.25 | H27: 24717.29 | I27: 32340.76 | J27: 36826.25 | K27: 40538.66
A28: Profit before tax | B28: 1060.35 | C28: 1445.49 | D28: 358.67 | E28: 1377.45 | F28: 3114.82 | G28: 3253.3 | H28: 5963.19 | I28: 11017.35 | J28: 14863.51 | K28: 16475.06
A29: Tax | B29: -352.56 | C29: 182.57 | D29: 37.74 | E29: 619.37 | F29: 99.1 | G29: -740.59 | H29: 632.71 | I29: 2888.2 | J29: 3868.64 | K29: 4248.07
A30: Net profit | B30: 1453.06 | C30: 1310.54 | D30: 380.13 | E30: 861.34 | F30: 3149.15 | G30: 4141.81 | H30: 5572.31 | I30: 8419.41 | J30: 11261.47 | K30: 11704.28
A31: Dividend Amount | B31: 288.17 | F31: 225.87 | G31: 809.54 | H31: 1071.08 | I31: 1616.35 | J31: 2188.81 | K31: 2458.2
A40: Quarters
A41: Report Date | B41: 45382 | C41: 45473 | D41: 45565 | E41: 45657 | F41: 45747 | G41: 45838 | H41: 45930 | I41: 46022 | J41: 46112 | K41: 46203
A42: Sales | B42: 14633.41 | C42: 15040.63 | D42: 15369.01 | E42: 15770.16 | F42: 15859.63 | G42: 16285.1 | H42: 16628.28 | I42: 17102.21 | J42: 17488.5 | K42: 18095.14
A43: Expenses | B43: 5378.16 | C43: 4994.32 | D43: 5143.73 | E43: 5101.71 | F43: 5097.49 | G43: 4880.15 | H43: 5108.39 | I43: 5492.5 | J43: 5811.46 | K43: 5946.06
A44: Other Income | B44: 2432.08 | C44: 2077.13 | D44: 2602.21 | E44: 2397.38 | F44: 2934.73 | G44: 1853.91 | H44: 2642.81 | I44: 2792.57 | J44: 2772.73 | K44: 2902.24
A45: Depreciation
A46: Interest | B46: 8609.13 | C46: 8860.51 | D46: 9153.5 | E46: 9345.18 | F46: 9467.06 | G46: 9924.09 | H46: 10039.71 | I46: 10202.9 | J46: 10371.96 | K46: 10656.86
A47: Profit before tax | B47: 3078.2 | C47: 3262.93 | D47: 3673.99 | E47: 3720.65 | F47: 4229.81 | G47: 3334.77 | H47: 4122.99 | I47: 4199.38 | J47: 4077.81 | K47: 4394.46
A48: Tax | B48: 817.89 | C48: 845.63 | D48: 933.96 | E48: 844.5 | F48: 1268.42 | G48: 1116.26 | H48: 1082.46 | I48: 1113.22 | J48: 962.61 | K48: 1094.98
A49: Net profit | B49: 2295.61 | C49: 2570.4 | D49: 2799.7 | E49: 2909.73 | F49: 2981.64 | G49: 2276.37 | H49: 3107.97 | I49: 3146.88 | J49: 3173.05 | K49: 3356.63
A50: Operating Profit | B50: 9255.25 | C50: 10046.31 | D50: 10225.28 | E50: 10668.45 | F50: 10762.14 | G50: 11404.95 | H50: 11519.89 | I50: 11609.71 | J50: 11677.04 | K50: 12149.08
A51: EBITDA | B51: 16892.02 | C51: 20164.6 | D51: 19850 | E51: 20404 | F51: 22268 | G51: 23828 | H51: 22359 | I51: 18164 | J51: 17822 | K51: 22113
A55: BALANCE SHEET
A56: Report Date | B56: 42825 | C56: 43190 | D56: 43555 | E56: 43921 | F56: 44286 | G56: 44651 | H56: 45016 | I56: 45382 | J56: 45747 | K56: 46112
...
